Workbook

Sheet Nasıl Kullanılır
B1: Alerjen Kontrol Listesi: Nasıl Kullanılır
B2: Bu dosya, dükkandaki her malzemenin etiketini tek tek kontrol edip menüdeki her ürünün alerjen bilgisini OTOMATİK çıkarmak için hazırlandı. Sitedeki menü ve alerjen tablosu da bu verilerden üretilecek.
B4: ADIMLAR
B5: 1. Dükkana giderken dosyayı telefonda/tablette açın ya da "Malzemeler" sayfasını yazdırın (yatay A4).
B6: 2. Her malzemenin paketinde "İçindekiler" ve "Alerjen uyarısı" kısmını okuyun. Alerjenler genelde KALIN yazılır. Emin olamadığınız kelimeler için "Etiket Sözlüğü" sayfasına bakın.
B7: 3. "Malzemeler" sayfasında 14 alerjen sütununun HEPSİNE açılır listeden bir değer seçin. Hiçbir hücreyi boş bırakmayın, çünkü BOŞ = KONTROL EDİLMEDİ demek.
B8: • Var: İçindekiler listesinde geçiyor.
B9: • Eser: "içerebilir", "eser miktarda içerebilir" veya "aynı tesiste üretilmiştir" uyarısı var.
B10: • Yok: Ne içindekilerde ne de uyarıda geçiyor.
B11: 4. Etiketin fotoğrafını çekin ve "Etiket fotoğrafı" sütununa Evet yazın. Fotoğrafları "malzeme-adi_tarih.jpg" adıyla tek bir klasörde saklayın. Denetimde ya da müşteri şikâyetinde kanıt olur.
B12: 5. Etiketi olmayan (açık alınan) ürünler için tedarikçiden "ürün teknik şartnamesi / spesifikasyon" isteyin, e-postayla yazılı gelsin.
B13: 6. "Reçeteler" sayfasına her menü ürününün hangi malzemelerden oluştuğunu yazın (her malzeme bir satır). "Alerjen Matrisi" sayfası kendiliğinden dolar.
... B29: • Bitmiş alerjen listesini işletme sahibi veya mutfak sorumlusu onaylamalı ("Alerjen Matrisi" altındaki onay satırı).

Sheet Malzemeler
A1: Malzeme Alerjen Kontrolü
A2: Her malzeme için 14 sütunun hepsini doldurun: Var / Eser / Yok. Boş = kontrol edilmedi.
A4: Malzeme | B4: Kategori | C4: Marka / Tedarikçi | D4: Dikkat edilecek alerjenler (ipucu) | E4: Gluten | F4: Kabuklular | G4: Yumurta | H4: Balık | I4: Yer fıstığı | J4: Soya | K4: Süt | L4: Sert kabuklu | M4: Kereviz | N4: Hardal | O4: Susam | P4: Sülfit | Q4: Acı bakla | R4: Yumuşakçalar | S4: Durum | T4: Etiket fotoğrafı | U4: Kontrol tarihi | V4: Kontrol eden | W4: Not
A5: ÖRNEK: X Fırın brioche ekmek (silinebilir) | B5: Ekmek & kaplama | C5: X Fırın | D5: gluten, süt, yumurta, susam, soya | E5: Var | F5: Yok | G5: Var | H5: Yok | I5: Eser | J5: Eser | K5: Var | L5: Eser | M5: Yok | N5: Yok | O5: Var | P5: Yok | Q5: Yok | R5: Yok | S5: =IF($A5="","",IF(COUNTA(E5:R5)=14,"Tamam","Eksik: "&(14-COUNTA(E5:R5)))) | T5: Evet | U5: 22.09.2026 | V5: Ali Y. | W5: Etikette "yer fıstığı ve sert kabuklu içerebilir" yazıyor
A6: Burger ekmeği (brioche / susamlı) | B6: Ekmek & kaplama | D6: gluten, süt, yumurta, susam, soya | S6: =IF($A6="","",IF(COUNTA(E6:R6)=14,"Tamam","Eksik: "&(14-COUNTA(E6:R6))))
A7: Tortilla / lavaş | B7: Ekmek & kaplama | D7: gluten, soya, süt | S7: =IF($A7="","",IF(COUNTA(E7:R7)=14,"Tamam","Eksik: "&(14-COUNTA(E7:R7))))
A8: Kaplama unu / çıtır karışım | B8: Ekmek & kaplama | D8: gluten, süt, yumurta, soya, hardal, kereviz | S8: =IF($A8="","",IF(COUNTA(E8:R8)=14,"Tamam","Eksik: "&(14-COUNTA(E8:R8))))
A9: Panko / galeta unu | B9: Ekmek & kaplama | D9: gluten, soya, süt | S9: =IF($A9="","",IF(COUNTA(E9:R9)=14,"Tamam","Eksik: "&(14-COUNTA(E9:R9))))
A10: Sıvı kaplama / tempura karışımı | B10: Ekmek & kaplama | D10: gluten, yumurta, süt | S10: =IF($A10="","",IF(COUNTA(E10:R10)=14,"Tamam","Eksik: "&(14-COUNTA(E10:R10))))
A11: Tavuk göğsü (çiğ, sade) | B11: Tavuk | D11: genelde yok. Marine geliyorsa alttaki satıra bakın | S11: =IF($A11="","",IF(COUNTA(E11:R11)=14,"Tamam","Eksik: "&(14-COUNTA(E11:R11))))
A12: Tavuk but / marine tavuk | B12: Tavuk | D12: soya, süt, hardal, kereviz, sülfit, gluten | S12: =IF($A12="","",IF(COUNTA(E12:R12)=14,"Tamam","Eksik: "&(14-COUNTA(E12:R12))))
A13: Hazır nugget / strips / şinitzel | B13: Tavuk | D13: gluten, soya, süt, kereviz, yumurta | S13: =IF($A13="","",IF(COUNTA(E13:R13)=14,"Tamam","Eksik: "&(14-COUNTA(E13:R13))))
A14: Marinasyon baharat karışımı | B14: Tavuk | D14: kereviz, hardal, soya, süt, gluten | S14: =IF($A14="","",IF(COUNTA(E14:R14)=14,"Tamam","Eksik: "&(14-COUNTA(E14:R14))))
A15: Mayonez | B15: Sos | D15: yumurta, hardal | S15: =IF($A15="","",IF(COUNTA(E15:R15)=14,"Tamam","Eksik: "&(14-COUNTA(E15:R15))))
A16: Ketçap | B16: Sos | D16: kereviz, sülfit | S16: =IF($A16="","",IF(COUNTA(E16:R16)=14,"Tamam","Eksik: "&(14-COUNTA(E16:R16))))
A17: Hardal sos | B17: Sos | D17: hardal, sülfit | S17: =IF($A17="","",IF(COUNTA(E17:R17)=14,"Tamam","Eksik: "&(14-COUNTA(E17:R17))))
... A43: Hazır tatlı (sufle, cookie, cheesecake) | B43: Tatlı | D43: gluten, süt, yumurta, sert kabuklu, soya, yer fıstığı | S43: =IF($A43="","",IF(COUNTA(E43:R43)=14,"Tamam","Eksik: "&(14-COUNTA(E43:R43))))
S44: =IF($A44="","",IF(COUNTA(E44:R44)=14,"Tamam","Eksik: "&(14-COUNTA(E44:R44))))
S45: =IF($A45="","",IF(COUNTA(E45:R45)=14,"Tamam","Eksik: "&(14-COUNTA(E45:R45))))
S46: =IF($A46="","",IF(COUNTA(E46:R46)=14,"Tamam","Eksik: "&(14-COUNTA(E46:R46))))
S47: =IF($A47="","",IF(COUNTA(E47:R47)=14,"Tamam","Eksik: "&(14-COUNTA(E47:R47))))
S48: =IF($A48="","",IF(COUNTA(E48:R48)=14,"Tamam","Eksik: "&(14-COUNTA(E48:R48))))
S49: =IF($A49="","",IF(COUNTA(E49:R49)=14,"Tamam","Eksik: "&(14-COUNTA(E49:R49))))
S50: =IF($A50="","",IF(COUNTA(E50:R50)=14,"Tamam","Eksik: "&(14-COUNTA(E50:R50))))
S51: =IF($A51="","",IF(COUNTA(E51:R51)=14,"Tamam","Eksik: "&(14-COUNTA(E51:R51))))
S52: =IF($A52="","",IF(COUNTA(E52:R52)=14,"Tamam","Eksik: "&(14-COUNTA(E52:R52))))
S53: =IF($A53="","",IF(COUNTA(E53:R53)=14,"Tamam","Eksik: "&(14-COUNTA(E53:R53))))
S54: =IF($A54="","",IF(COUNTA(E54:R54)=14,"Tamam","Eksik: "&(14-COUNTA(E54:R54))))
S55: =IF($A55="","",IF(COUNTA(E55:R55)=14,"Tamam","Eksik: "&(14-COUNTA(E55:R55))))
... S100: =IF($A100="","",IF(COUNTA(E100:R100)=14,"Tamam","Eksik: "&(14-COUNTA(E100:R100))))

Sheet Reçeteler
A1: Ürün Reçeteleri
A2: Her satır = bir ürün + o ürünün bir malzemesi. Ürünü önce "Alerjen Matrisi" sayfasına, malzemeyi "Malzemeler" sayfasına ekleyin. Gri sütunlar otomatik.
A4: Ürün | B4: Malzeme | C4: Gluten | D4: Kabuklular | E4: Yumurta | F4: Balık | G4: Yer fıstığı | H4: Soya | I4: Süt | J4: Sert kabuklu | K4: Kereviz | L4: Hardal | M4: Susam | N4: Sülfit | O4: Acı bakla | P4: Yumuşakçalar
A5: Örnek: Klasik Tavuk Burger | B5: Burger ekmeği (brioche / susamlı) | C5: =IF($B5="","",IFERROR(IF(INDEX(Malzemeler!$E$5:$E$100,MATCH($B5,Malzemeler!$A$5:$A$100,0))="","Bilinmiyor",INDEX(Malzemeler!$E$5:$E$100,MATCH($B5,Malzemeler!$A$5:$A$100,0))),"Bilinmiyor")) | D5: =IF($B5="","",IFERROR(IF(INDEX(Malzemeler!$F$5:$F$100,MATCH($B5,Malzemeler!$A$5:$A$100,0))="","Bilinmiyor",INDEX(Malzemeler!$F$5:$F$100,MATCH($B5,Malzemeler!$A$5:$A$100,0))),"Bilinmiyor")) | E5: =IF($B5="","",IFERROR(IF(INDEX(Malzemeler!$G$5:$G$100,MATCH($B5,Malzemeler!$A$5:$A$100,0))="","Bilinmiyor",INDEX(Malzemeler!$G$5:$G$100,MATCH($B5,Malzemeler!$A$5:$A$100,0))),"Bilinmiyor")) | F5: =IF($B5="","",IFERROR(IF(INDEX(Malzemeler!$H$5:$H$100,MATCH($B5,Malzemeler!$A$5:$A$100,0))="","Bilinmiyor",INDEX(Malzemeler!$H$5:$H$100,MATCH($B5,Malzemeler!$A$5:$A$100,0))),"Bilinmiyor")) | G5: =IF($B5="","",IFERROR(IF(INDEX(Malzemeler!$I$5:$I$100,MATCH($B5,Malzemeler!$A$5:$A$100,0))="","Bilinmiyor",INDEX(Malzemeler!$I$5:$I$100,MATCH($B5,Malzemeler!$A$5:$A$100,0))),"Bilinmiyor")) | H5: =IF($B5="","",IFERROR(IF(INDEX(Malzemeler!$J$5:$J$100,MATCH($B5,Malzemeler!$A$5:$A$100,0))="","Bilinmiyor",INDEX(Malzemeler!$J$5:$J$100,MATCH($B5,Malzemeler!$A$5:$A$100,0))),"Bilinmiyor")) | I5: =IF($B5="","",IFERROR(IF(INDEX(Malzemeler!$K$5:$K$100,MATCH($B5,Malzemeler!$A$5:$A$100,0))="","Bilinmiyor",INDEX(Malzemeler!$K$5:$K$100,MATCH($B5,Malzemeler!$A$5:$A$100,0))),"Bilinmiyor")) | J5: =IF($B5="","",IFERROR(IF(INDEX(Malzemeler!$L$5:$L$100,MATCH($B5,Malzemeler!$A$5:$A$100,0))="","Bilinmiyor",INDEX(Malzemeler!$L$5:$L$100,MATCH($B5,Malzemeler!$A$5:$A$100,0))),"Bilinmiyor")) | K5: =IF($B5="","",IFERROR(IF(INDEX(Malzemeler!$M$5:$M$100,MATCH($B5,Malzemeler!$A$5:$A$100,0))="","Bilinmiyor",INDEX(Malzemeler!$M$5:$M$100,MATCH($B5,Malzemeler!$A$5:$A$100,0))),"Bilinmiyor")) | L5: =IF($B5="","",IFERROR(IF(INDEX(Malzemeler!$N$5:$N$100,MATCH($B5,Malzemeler!$A$5:$A$100,0))="","Bilinmiyor",INDEX(Malzemeler!$N$5:$N$100,MATCH($B5,Malzemeler!$A$5:$A$100,0))),"Bilinmiyor")) | M5: =IF($B5="","",IFERROR(IF(INDEX(Malzemeler!$O$5:$O$100,MATCH($B5,Malzemeler!$A$5:$A$100,0))="","Bilinmiyor",INDEX(Malzemeler!$O$5:$O$100,MATCH($B5,Malzemeler!$A$5:$A$100,0))),"Bilinmiyor")) | N5: =IF($B5="","",IFERROR(IF(INDEX(Malzemeler!$P$5:$P$100,MATCH($B5,Malzemeler!$A$5:$A$100,0))="","Bilinmiyor",INDEX(Malzemeler!$P$5:$P$100,MATCH($B5,Malzemeler!$A$5:$A$100,0))),"Bilinmiyor")) | O5: =IF($B5="","",IFERROR(IF(INDEX(Malzemeler!$Q$5:$Q$100,MATCH($B5,Malzemeler!$A$5:$A$100,0))="","Bilinmiyor",INDEX(Malzemeler!$Q$5:$Q$100,MATCH($B5,Malzemeler!$A$5:$A$100,0))),"Bilinmiyor")) | P5: =IF($B5="","",IFERROR(IF(INDEX(Malzemeler!$R$5:$R$100,MATCH($B5,Malzemeler!$A$5:$A$100,0))="","Bilinmiyor",INDEX(Malzemeler!$R$5:$R$100,MATCH($B5,Malzemeler!$A$5:$A$100,0))),"Bilinmiyor"))
A6: Örnek: Klasik Tavuk Burger | B6: Tavuk göğsü (çiğ, sade) | C6: =IF($B6="","",IFERROR(IF(INDEX(Malzemeler!$E$5:$E$100,MATCH($B6,Malzemeler!$A$5:$A$100,0))="","Bilinmiyor",INDEX(Malzemeler!$E$5:$E$100,MATCH($B6,Malzemeler!$A$5:$A$100,0))),"Bilinmiyor")) | D6: =IF($B6="","",IFERROR(IF(INDEX(Malzemeler!$F$5:$F$100,MATCH($B6,Malzemeler!$A$5:$A$100,0))="","Bilinmiyor",INDEX(Malzemeler!$F$5:$F$100,MATCH($B6,Malzemeler!$A$5:$A$100,0))),"Bilinmiyor")) | E6: =IF($B6="","",IFERROR(IF(INDEX(Malzemeler!$G$5:$G$100,MATCH($B6,Malzemeler!$A$5:$A$100,0))="","Bilinmiyor",INDEX(Malzemeler!$G$5:$G$100,MATCH($B6,Malzemeler!$A$5:$A$100,0))),"Bilinmiyor")) | F6: =IF($B6="","",IFERROR(IF(INDEX(Malzemeler!$H$5:$H$100,MATCH($B6,Malzemeler!$A$5:$A$100,0))="","Bilinmiyor",INDEX(Malzemeler!$H$5:$H$100,MATCH($B6,Malzemeler!$A$5:$A$100,0))),"Bilinmiyor")) | G6: =IF($B6="","",IFERROR(IF(INDEX(Malzemeler!$I$5:$I$100,MATCH($B6,Malzemeler!$A$5:$A$100,0))="","Bilinmiyor",INDEX(Malzemeler!$I$5:$I$100,MATCH($B6,Malzemeler!$A$5:$A$100,0))),"Bilinmiyor")) | H6: =IF($B6="","",IFERROR(IF(INDEX(Malzemeler!$J$5:$J$100,MATCH($B6,Malzemeler!$A$5:$A$100,0))="","Bilinmiyor",INDEX(Malzemeler!$J$5:$J$100,MATCH($B6,Malzemeler!$A$5:$A$100,0))),"Bilinmiyor")) | I6: =IF($B6="","",IFERROR(IF(INDEX(Malzemeler!$K$5:$K$100,MATCH($B6,Malzemeler!$A$5:$A$100,0))="","Bilinmiyor",INDEX(Malzemeler!$K$5:$K$100,MATCH($B6,Malzemeler!$A$5:$A$100,0))),"Bilinmiyor")) | J6: =IF($B6="","",IFERROR(IF(INDEX(Malzemeler!$L$5:$L$100,MATCH($B6,Malzemeler!$A$5:$A$100,0))="","Bilinmiyor",INDEX(Malzemeler!$L$5:$L$100,MATCH($B6,Malzemeler!$A$5:$A$100,0))),"Bilinmiyor")) | K6: =IF($B6="","",IFERROR(IF(INDEX(Malzemeler!$M$5:$M$100,MATCH($B6,Malzemeler!$A$5:$A$100,0))="","Bilinmiyor",INDEX(Malzemeler!$M$5:$M$100,MATCH($B6,Malzemeler!$A$5:$A$100,0))),"Bilinmiyor")) | L6: =IF($B6="","",IFERROR(IF(INDEX(Malzemeler!$N$5:$N$100,MATCH($B6,Malzemeler!$A$5:$A$100,0))="","Bilinmiyor",INDEX(Malzemeler!$N$5:$N$100,MATCH($B6,Malzemeler!$A$5:$A$100,0))),"Bilinmiyor")) | M6: =IF($B6="","",IFERROR(IF(INDEX(Malzemeler!$O$5:$O$100,MATCH($B6,Malzemeler!$A$5:$A$100,0))="","Bilinmiyor",INDEX(Malzemeler!$O$5:$O$100,MATCH($B6,Malzemeler!$A$5:$A$100,0))),"Bilinmiyor")) | N6: =IF($B6="","",IFERROR(IF(INDEX(Malzemeler!$P$5:$P$100,MATCH($B6,Malzemeler!$A$5:$A$100,0))="","Bilinmiyor",INDEX(Malzemeler!$P$5:$P$100,MATCH($B6,Malzemeler!$A$5:$A$100,0))),"Bilinmiyor")) | O6: =IF($B6="","",IFERROR(IF(INDEX(Malzemeler!$Q$5:$Q$100,MATCH($B6,Malzemeler!$A$5:$A$100,0))="","Bilinmiyor",INDEX(Malzemeler!$Q$5:$Q$100,MATCH($B6,Malzemeler!$A$5:$A$100,0))),"Bilinmiyor")) | P6: =IF($B6="","",IFERROR(IF(INDEX(Malzemeler!$R$5:$R$100,MATCH($B6,Malzemeler!$A$5:$A$100,0))="","Bilinmiyor",INDEX(Malzemeler!$R$5:$R$100,MATCH($B6,Malzemeler!$A$5:$A$100,0))),"Bilinmiyor"))
A7: Örnek: Klasik Tavuk Burger | B7: Kaplama unu / çıtır karışım | C7: =IF($B7="","",IFERROR(IF(INDEX(Malzemeler!$E$5:$E$100,MATCH($B7,Malzemeler!$A$5:$A$100,0))="","Bilinmiyor",INDEX(Malzemeler!$E$5:$E$100,MATCH($B7,Malzemeler!$A$5:$A$100,0))),"Bilinmiyor")) | D7: =IF($B7="","",IFERROR(IF(INDEX(Malzemeler!$F$5:$F$100,MATCH($B7,Malzemeler!$A$5:$A$100,0))="","Bilinmiyor",INDEX(Malzemeler!$F$5:$F$100,MATCH($B7,Malzemeler!$A$5:$A$100,0))),"Bilinmiyor")) | E7: =IF($B7="","",IFERROR(IF(INDEX(Malzemeler!$G$5:$G$100,MATCH($B7,Malzemeler!$A$5:$A$100,0))="","Bilinmiyor",INDEX(Malzemeler!$G$5:$G$100,MATCH($B7,Malzemeler!$A$5:$A$100,0))),"Bilinmiyor")) | F7: =IF($B7="","",IFERROR(IF(INDEX(Malzemeler!$H$5:$H$100,MATCH($B7,Malzemeler!$A$5:$A$100,0))="","Bilinmiyor",INDEX(Malzemeler!$H$5:$H$100,MATCH($B7,Malzemeler!$A$5:$A$100,0))),"Bilinmiyor")) | G7: =IF($B7="","",IFERROR(IF(INDEX(Malzemeler!$I$5:$I$100,MATCH($B7,Malzemeler!$A$5:$A$100,0))="","Bilinmiyor",INDEX(Malzemeler!$I$5:$I$100,MATCH($B7,Malzemeler!$A$5:$A$100,0))),"Bilinmiyor")) | H7: =IF($B7="","",IFERROR(IF(INDEX(Malzemeler!$J$5:$J$100,MATCH($B7,Malzemeler!$A$5:$A$100,0))="","Bilinmiyor",INDEX(Malzemeler!$J$5:$J$100,MATCH($B7,Malzemeler!$A$5:$A$100,0))),"Bilinmiyor")) | I7: =IF($B7="","",IFERROR(IF(INDEX(Malzemeler!$K$5:$K$100,MATCH($B7,Malzemeler!$A$5:$A$100,0))="","Bilinmiyor",INDEX(Malzemeler!$K$5:$K$100,MATCH($B7,Malzemeler!$A$5:$A$100,0))),"Bilinmiyor")) | J7: =IF($B7="","",IFERROR(IF(INDEX(Malzemeler!$L$5:$L$100,MATCH($B7,Malzemeler!$A$5:$A$100,0))="","Bilinmiyor",INDEX(Malzemeler!$L$5:$L$100,MATCH($B7,Malzemeler!$A$5:$A$100,0))),"Bilinmiyor")) | K7: =IF($B7="","",IFERROR(IF(INDEX(Malzemeler!$M$5:$M$100,MATCH($B7,Malzemeler!$A$5:$A$100,0))="","Bilinmiyor",INDEX(Malzemeler!$M$5:$M$100,MATCH($B7,Malzemeler!$A$5:$A$100,0))),"Bilinmiyor")) | L7: =IF($B7="","",IFERROR(IF(INDEX(Malzemeler!$N$5:$N$100,MATCH($B7,Malzemeler!$A$5:$A$100,0))="","Bilinmiyor",INDEX(Malzemeler!$N$5:$N$100,MATCH($B7,Malzemeler!$A$5:$A$100,0))),"Bilinmiyor")) | M7: =IF($B7="","",IFERROR(IF(INDEX(Malzemeler!$O$5:$O$100,MATCH($B7,Malzemeler!$A$5:$A$100,0))="","Bilinmiyor",INDEX(Malzemeler!$O$5:$O$100,MATCH($B7,Malzemeler!$A$5:$A$100,0))),"Bilinmiyor")) | N7: =IF($B7="","",IFERROR(IF(INDEX(Malzemeler!$P$5:$P$100,MATCH($B7,Malzemeler!$A$5:$A$100,0))="","Bilinmiyor",INDEX(Malzemeler!$P$5:$P$100,MATCH($B7,Malzemeler!$A$5:$A$100,0))),"Bilinmiyor")) | O7: =IF($B7="","",IFERROR(IF(INDEX(Malzemeler!$Q$5:$Q$100,MATCH($B7,Malzemeler!$A$5:$A$100,0))="","Bilinmiyor",INDEX(Malzemeler!$Q$5:$Q$100,MATCH($B7,Malzemeler!$A$5:$A$100,0))),"Bilinmiyor")) | P7: =IF($B7="","",IFERROR(IF(INDEX(Malzemeler!$R$5:$R$100,MATCH($B7,Malzemeler!$A$5:$A$100,0))="","Bilinmiyor",INDEX(Malzemeler!$R$5:$R$100,MATCH($B7,Malzemeler!$A$5:$A$100,0))),"Bilinmiyor"))
A8: Örnek: Klasik Tavuk Burger | B8: Mayonez | C8: =IF($B8="","",IFERROR(IF(INDEX(Malzemeler!$E$5:$E$100,MATCH($B8,Malzemeler!$A$5:$A$100,0))="","Bilinmiyor",INDEX(Malzemeler!$E$5:$E$100,MATCH($B8,Malzemeler!$A$5:$A$100,0))),"Bilinmiyor")) | D8: =IF($B8="","",IFERROR(IF(INDEX(Malzemeler!$F$5:$F$100,MATCH($B8,Malzemeler!$A$5:$A$100,0))="","Bilinmiyor",INDEX(Malzemeler!$F$5:$F$100,MATCH($B8,Malzemeler!$A$5:$A$100,0))),"Bilinmiyor")) | E8: =IF($B8="","",IFERROR(IF(INDEX(Malzemeler!$G$5:$G$100,MATCH($B8,Malzemeler!$A$5:$A$100,0))="","Bilinmiyor",INDEX(Malzemeler!$G$5:$G$100,MATCH($B8,Malzemeler!$A$5:$A$100,0))),"Bilinmiyor")) | F8: =IF($B8="","",IFERROR(IF(INDEX(Malzemeler!$H$5:$H$100,MATCH($B8,Malzemeler!$A$5:$A$100,0))="","Bilinmiyor",INDEX(Malzemeler!$H$5:$H$100,MATCH($B8,Malzemeler!$A$5:$A$100,0))),"Bilinmiyor")) | G8: =IF($B8="","",IFERROR(IF(INDEX(Malzemeler!$I$5:$I$100,MATCH($B8,Malzemeler!$A$5:$A$100,0))="","Bilinmiyor",INDEX(Malzemeler!$I$5:$I$100,MATCH($B8,Malzemeler!$A$5:$A$100,0))),"Bilinmiyor")) | H8: =IF($B8="","",IFERROR(IF(INDEX(Malzemeler!$J$5:$J$100,MATCH($B8,Malzemeler!$A$5:$A$100,0))="","Bilinmiyor",INDEX(Malzemeler!$J$5:$J$100,MATCH($B8,Malzemeler!$A$5:$A$100,0))),"Bilinmiyor")) | I8: =IF($B8="","",IFERROR(IF(INDEX(Malzemeler!$K$5:$K$100,MATCH($B8,Malzemeler!$A$5:$A$100,0))="","Bilinmiyor",INDEX(Malzemeler!$K$5:$K$100,MATCH($B8,Malzemeler!$A$5:$A$100,0))),"Bilinmiyor")) | J8: =IF($B8="","",IFERROR(IF(INDEX(Malzemeler!$L$5:$L$100,MATCH($B8,Malzemeler!$A$5:$A$100,0))="","Bilinmiyor",INDEX(Malzemeler!$L$5:$L$100,MATCH($B8,Malzemeler!$A$5:$A$100,0))),"Bilinmiyor")) | K8: =IF($B8="","",IFERROR(IF(INDEX(Malzemeler!$M$5:$M$100,MATCH($B8,Malzemeler!$A$5:$A$100,0))="","Bilinmiyor",INDEX(Malzemeler!$M$5:$M$100,MATCH($B8,Malzemeler!$A$5:$A$100,0))),"Bilinmiyor")) | L8: =IF($B8="","",IFERROR(IF(INDEX(Malzemeler!$N$5:$N$100,MATCH($B8,Malzemeler!$A$5:$A$100,0))="","Bilinmiyor",INDEX(Malzemeler!$N$5:$N$100,MATCH($B8,Malzemeler!$A$5:$A$100,0))),"Bilinmiyor")) | M8: =IF($B8="","",IFERROR(IF(INDEX(Malzemeler!$O$5:$O$100,MATCH($B8,Malzemeler!$A$5:$A$100,0))="","Bilinmiyor",INDEX(Malzemeler!$O$5:$O$100,MATCH($B8,Malzemeler!$A$5:$A$100,0))),"Bilinmiyor")) | N8: =IF($B8="","",IFERROR(IF(INDEX(Malzemeler!$P$5:$P$100,MATCH($B8,Malzemeler!$A$5:$A$100,0))="","Bilinmiyor",INDEX(Malzemeler!$P$5:$P$100,MATCH($B8,Malzemeler!$A$5:$A$100,0))),"Bilinmiyor")) | O8: =IF($B8="","",IFERROR(IF(INDEX(Malzemeler!$Q$5:$Q$100,MATCH($B8,Malzemeler!$A$5:$A$100,0))="","Bilinmiyor",INDEX(Malzemeler!$Q$5:$Q$100,MATCH($B8,Malzemeler!$A$5:$A$100,0))),"Bilinmiyor")) | P8: =IF($B8="","",IFERROR(IF(INDEX(Malzemeler!$R$5:$R$100,MATCH($B8,Malzemeler!$A$5:$A$100,0))="","Bilinmiyor",INDEX(Malzemeler!$R$5:$R$100,MATCH($B8,Malzemeler!$A$5:$A$100,0))),"Bilinmiyor"))
A9: Örnek: Klasik Tavuk Burger | B9: Salatalık turşusu | C9: =IF($B9="","",IFERROR(IF(INDEX(Malzemeler!$E$5:$E$100,MATCH($B9,Malzemeler!$A$5:$A$100,0))="","Bilinmiyor",INDEX(Malzemeler!$E$5:$E$100,MATCH($B9,Malzemeler!$A$5:$A$100,0))),"Bilinmiyor")) | D9: =IF($B9="","",IFERROR(IF(INDEX(Malzemeler!$F$5:$F$100,MATCH($B9,Malzemeler!$A$5:$A$100,0))="","Bilinmiyor",INDEX(Malzemeler!$F$5:$F$100,MATCH($B9,Malzemeler!$A$5:$A$100,0))),"Bilinmiyor")) | E9: =IF($B9="","",IFERROR(IF(INDEX(Malzemeler!$G$5:$G$100,MATCH($B9,Malzemeler!$A$5:$A$100,0))="","Bilinmiyor",INDEX(Malzemeler!$G$5:$G$100,MATCH($B9,Malzemeler!$A$5:$A$100,0))),"Bilinmiyor")) | F9: =IF($B9="","",IFERROR(IF(INDEX(Malzemeler!$H$5:$H$100,MATCH($B9,Malzemeler!$A$5:$A$100,0))="","Bilinmiyor",INDEX(Malzemeler!$H$5:$H$100,MATCH($B9,Malzemeler!$A$5:$A$100,0))),"Bilinmiyor")) | G9: =IF($B9="","",IFERROR(IF(INDEX(Malzemeler!$I$5:$I$100,MATCH($B9,Malzemeler!$A$5:$A$100,0))="","Bilinmiyor",INDEX(Malzemeler!$I$5:$I$100,MATCH($B9,Malzemeler!$A$5:$A$100,0))),"Bilinmiyor")) | H9: =IF($B9="","",IFERROR(IF(INDEX(Malzemeler!$J$5:$J$100,MATCH($B9,Malzemeler!$A$5:$A$100,0))="","Bilinmiyor",INDEX(Malzemeler!$J$5:$J$100,MATCH($B9,Malzemeler!$A$5:$A$100,0))),"Bilinmiyor")) | I9: =IF($B9="","",IFERROR(IF(INDEX(Malzemeler!$K$5:$K$100,MATCH($B9,Malzemeler!$A$5:$A$100,0))="","Bilinmiyor",INDEX(Malzemeler!$K$5:$K$100,MATCH($B9,Malzemeler!$A$5:$A$100,0))),"Bilinmiyor")) | J9: =IF($B9="","",IFERROR(IF(INDEX(Malzemeler!$L$5:$L$100,MATCH($B9,Malzemeler!$A$5:$A$100,0))="","Bilinmiyor",INDEX(Malzemeler!$L$5:$L$100,MATCH($B9,Malzemeler!$A$5:$A$100,0))),"Bilinmiyor")) | K9: =IF($B9="","",IFERROR(IF(INDEX(Malzemeler!$M$5:$M$100,MATCH($B9,Malzemeler!$A$5:$A$100,0))="","Bilinmiyor",INDEX(Malzemeler!$M$5:$M$100,MATCH($B9,Malzemeler!$A$5:$A$100,0))),"Bilinmiyor")) | L9: =IF($B9="","",IFERROR(IF(INDEX(Malzemeler!$N$5:$N$100,MATCH($B9,Malzemeler!$A$5:$A$100,0))="","Bilinmiyor",INDEX(Malzemeler!$N$5:$N$100,MATCH($B9,Malzemeler!$A$5:$A$100,0))),"Bilinmiyor")) | M9: =IF($B9="","",IFERROR(IF(INDEX(Malzemeler!$O$5:$O$100,MATCH($B9,Malzemeler!$A$5:$A$100,0))="","Bilinmiyor",INDEX(Malzemeler!$O$5:$O$100,MATCH($B9,Malzemeler!$A$5:$A$100,0))),"Bilinmiyor")) | N9: =IF($B9="","",IFERROR(IF(INDEX(Malzemeler!$P$5:$P$100,MATCH($B9,Malzemeler!$A$5:$A$100,0))="","Bilinmiyor",INDEX(Malzemeler!$P$5:$P$100,MATCH($B9,Malzemeler!$A$5:$A$100,0))),"Bilinmiyor")) | O9: =IF($B9="","",IFERROR(IF(INDEX(Malzemeler!$Q$5:$Q$100,MATCH($B9,Malzemeler!$A$5:$A$100,0))="","Bilinmiyor",INDEX(Malzemeler!$Q$5:$Q$100,MATCH($B9,Malzemeler!$A$5:$A$100,0))),"Bilinmiyor")) | P9: =IF($B9="","",IFERROR(IF(INDEX(Malzemeler!$R$5:$R$100,MATCH($B9,Malzemeler!$A$5:$A$100,0))="","Bilinmiyor",INDEX(Malzemeler!$R$5:$R$100,MATCH($B9,Malzemeler!$A$5:$A$100,0))),"Bilinmiyor"))
A10: Örnek: Klasik Tavuk Burger | B10: Marul | C10: =IF($B10="","",IFERROR(IF(INDEX(Malzemeler!$E$5:$E$100,MATCH($B10,Malzemeler!$A$5:$A$100,0))="","Bilinmiyor",INDEX(Malzemeler!$E$5:$E$100,MATCH($B10,Malzemeler!$A$5:$A$100,0))),"Bilinmiyor")) | D10: =IF($B10="","",IFERROR(IF(INDEX(Malzemeler!$F$5:$F$100,MATCH($B10,Malzemeler!$A$5:$A$100,0))="","Bilinmiyor",INDEX(Malzemeler!$F$5:$F$100,MATCH($B10,Malzemeler!$A$5:$A$100,0))),"Bilinmiyor")) | E10: =IF($B10="","",IFERROR(IF(INDEX(Malzemeler!$G$5:$G$100,MATCH($B10,Malzemeler!$A$5:$A$100,0))="","Bilinmiyor",INDEX(Malzemeler!$G$5:$G$100,MATCH($B10,Malzemeler!$A$5:$A$100,0))),"Bilinmiyor")) | F10: =IF($B10="","",IFERROR(IF(INDEX(Malzemeler!$H$5:$H$100,MATCH($B10,Malzemeler!$A$5:$A$100,0))="","Bilinmiyor",INDEX(Malzemeler!$H$5:$H$100,MATCH($B10,Malzemeler!$A$5:$A$100,0))),"Bilinmiyor")) | G10: =IF($B10="","",IFERROR(IF(INDEX(Malzemeler!$I$5:$I$100,MATCH($B10,Malzemeler!$A$5:$A$100,0))="","Bilinmiyor",INDEX(Malzemeler!$I$5:$I$100,MATCH($B10,Malzemeler!$A$5:$A$100,0))),"Bilinmiyor")) | H10: =IF($B10="","",IFERROR(IF(INDEX(Malzemeler!$J$5:$J$100,MATCH($B10,Malzemeler!$A$5:$A$100,0))="","Bilinmiyor",INDEX(Malzemeler!$J$5:$J$100,MATCH($B10,Malzemeler!$A$5:$A$100,0))),"Bilinmiyor")) | I10: =IF($B10="","",IFERROR(IF(INDEX(Malzemeler!$K$5:$K$100,MATCH($B10,Malzemeler!$A$5:$A$100,0))="","Bilinmiyor",INDEX(Malzemeler!$K$5:$K$100,MATCH($B10,Malzemeler!$A$5:$A$100,0))),"Bilinmiyor")) | J10: =IF($B10="","",IFERROR(IF(INDEX(Malzemeler!$L$5:$L$100,MATCH($B10,Malzemeler!$A$5:$A$100,0))="","Bilinmiyor",INDEX(Malzemeler!$L$5:$L$100,MATCH($B10,Malzemeler!$A$5:$A$100,0))),"Bilinmiyor")) | K10: =IF($B10="","",IFERROR(IF(INDEX(Malzemeler!$M$5:$M$100,MATCH($B10,Malzemeler!$A$5:$A$100,0))="","Bilinmiyor",INDEX(Malzemeler!$M$5:$M$100,MATCH($B10,Malzemeler!$A$5:$A$100,0))),"Bilinmiyor")) | L10: =IF($B10="","",IFERROR(IF(INDEX(Malzemeler!$N$5:$N$100,MATCH($B10,Malzemeler!$A$5:$A$100,0))="","Bilinmiyor",INDEX(Malzemeler!$N$5:$N$100,MATCH($B10,Malzemeler!$A$5:$A$100,0))),"Bilinmiyor")) | M10: =IF($B10="","",IFERROR(IF(INDEX(Malzemeler!$O$5:$O$100,MATCH($B10,Malzemeler!$A$5:$A$100,0))="","Bilinmiyor",INDEX(Malzemeler!$O$5:$O$100,MATCH($B10,Malzemeler!$A$5:$A$100,0))),"Bilinmiyor")) | N10: =IF($B10="","",IFERROR(IF(INDEX(Malzemeler!$P$5:$P$100,MATCH($B10,Malzemeler!$A$5:$A$100,0))="","Bilinmiyor",INDEX(Malzemeler!$P$5:$P$100,MATCH($B10,Malzemeler!$A$5:$A$100,0))),"Bilinmiyor")) | O10: =IF($B10="","",IFERROR(IF(INDEX(Malzemeler!$Q$5:$Q$100,MATCH($B10,Malzemeler!$A$5:$A$100,0))="","Bilinmiyor",INDEX(Malzemeler!$Q$5:$Q$100,MATCH($B10,Malzemeler!$A$5:$A$100,0))),"Bilinmiyor")) | P10: =IF($B10="","",IFERROR(IF(INDEX(Malzemeler!$R$5:$R$100,MATCH($B10,Malzemeler!$A$5:$A$100,0))="","Bilinmiyor",INDEX(Malzemeler!$R$5:$R$100,MATCH($B10,Malzemeler!$A$5:$A$100,0))),"Bilinmiyor"))
A11: Örnek: Klasik Tavuk Burger | B11: Domates | C11: =IF($B11="","",IFERROR(IF(INDEX(Malzemeler!$E$5:$E$100,MATCH($B11,Malzemeler!$A$5:$A$100,0))="","Bilinmiyor",INDEX(Malzemeler!$E$5:$E$100,MATCH($B11,Malzemeler!$A$5:$A$100,0))),"Bilinmiyor")) | D11: =IF($B11="","",IFERROR(IF(INDEX(Malzemeler!$F$5:$F$100,MATCH($B11,Malzemeler!$A$5:$A$100,0))="","Bilinmiyor",INDEX(Malzemeler!$F$5:$F$100,MATCH($B11,Malzemeler!$A$5:$A$100,0))),"Bilinmiyor")) | E11: =IF($B11="","",IFERROR(IF(INDEX(Malzemeler!$G$5:$G$100,MATCH($B11,Malzemeler!$A$5:$A$100,0))="","Bilinmiyor",INDEX(Malzemeler!$G$5:$G$100,MATCH($B11,Malzemeler!$A$5:$A$100,0))),"Bilinmiyor")) | F11: =IF($B11="","",IFERROR(IF(INDEX(Malzemeler!$H$5:$H$100,MATCH($B11,Malzemeler!$A$5:$A$100,0))="","Bilinmiyor",INDEX(Malzemeler!$H$5:$H$100,MATCH($B11,Malzemeler!$A$5:$A$100,0))),"Bilinmiyor")) | G11: =IF($B11="","",IFERROR(IF(INDEX(Malzemeler!$I$5:$I$100,MATCH($B11,Malzemeler!$A$5:$A$100,0))="","Bilinmiyor",INDEX(Malzemeler!$I$5:$I$100,MATCH($B11,Malzemeler!$A$5:$A$100,0))),"Bilinmiyor")) | H11: =IF($B11="","",IFERROR(IF(INDEX(Malzemeler!$J$5:$J$100,MATCH($B11,Malzemeler!$A$5:$A$100,0))="","Bilinmiyor",INDEX(Malzemeler!$J$5:$J$100,MATCH($B11,Malzemeler!$A$5:$A$100,0))),"Bilinmiyor")) | I11: =IF($B11="","",IFERROR(IF(INDEX(Malzemeler!$K$5:$K$100,MATCH($B11,Malzemeler!$A$5:$A$100,0))="","Bilinmiyor",INDEX(Malzemeler!$K$5:$K$100,MATCH($B11,Malzemeler!$A$5:$A$100,0))),"Bilinmiyor")) | J11: =IF($B11="","",IFERROR(IF(INDEX(Malzemeler!$L$5:$L$100,MATCH($B11,Malzemeler!$A$5:$A$100,0))="","Bilinmiyor",INDEX(Malzemeler!$L$5:$L$100,MATCH($B11,Malzemeler!$A$5:$A$100,0))),"Bilinmiyor")) | K11: =IF($B11="","",IFERROR(IF(INDEX(Malzemeler!$M$5:$M$100,MATCH($B11,Malzemeler!$A$5:$A$100,0))="","Bilinmiyor",INDEX(Malzemeler!$M$5:$M$100,MATCH($B11,Malzemeler!$A$5:$A$100,0))),"Bilinmiyor")) | L11: =IF($B11="","",IFERROR(IF(INDEX(Malzemeler!$N$5:$N$100,MATCH($B11,Malzemeler!$A$5:$A$100,0))="","Bilinmiyor",INDEX(Malzemeler!$N$5:$N$100,MATCH($B11,Malzemeler!$A$5:$A$100,0))),"Bilinmiyor")) | M11: =IF($B11="","",IFERROR(IF(INDEX(Malzemeler!$O$5:$O$100,MATCH($B11,Malzemeler!$A$5:$A$100,0))="","Bilinmiyor",INDEX(Malzemeler!$O$5:$O$100,MATCH($B11,Malzemeler!$A$5:$A$100,0))),"Bilinmiyor")) | N11: =IF($B11="","",IFERROR(IF(INDEX(Malzemeler!$P$5:$P$100,MATCH($B11,Malzemeler!$A$5:$A$100,0))="","Bilinmiyor",INDEX(Malzemeler!$P$5:$P$100,MATCH($B11,Malzemeler!$A$5:$A$100,0))),"Bilinmiyor")) | O11: =IF($B11="","",IFERROR(IF(INDEX(Malzemeler!$Q$5:$Q$100,MATCH($B11,Malzemeler!$A$5:$A$100,0))="","Bilinmiyor",INDEX(Malzemeler!$Q$5:$Q$100,MATCH($B11,Malzemeler!$A$5:$A$100,0))),"Bilinmiyor")) | P11: =IF($B11="","",IFERROR(IF(INDEX(Malzemeler!$R$5:$R$100,MATCH($B11,Malzemeler!$A$5:$A$100,0))="","Bilinmiyor",INDEX(Malzemeler!$R$5:$R$100,MATCH($B11,Malzemeler!$A$5:$A$100,0))),"Bilinmiyor"))
A12: Örnek: Klasik Tavuk Burger | B12: Cheddar dilim peynir | C12: =IF($B12="","",IFERROR(IF(INDEX(Malzemeler!$E$5:$E$100,MATCH($B12,Malzemeler!$A$5:$A$100,0))="","Bilinmiyor",INDEX(Malzemeler!$E$5:$E$100,MATCH($B12,Malzemeler!$A$5:$A$100,0))),"Bilinmiyor")) | D12: =IF($B12="","",IFERROR(IF(INDEX(Malzemeler!$F$5:$F$100,MATCH($B12,Malzemeler!$A$5:$A$100,0))="","Bilinmiyor",INDEX(Malzemeler!$F$5:$F$100,MATCH($B12,Malzemeler!$A$5:$A$100,0))),"Bilinmiyor")) | E12: =IF($B12="","",IFERROR(IF(INDEX(Malzemeler!$G$5:$G$100,MATCH($B12,Malzemeler!$A$5:$A$100,0))="","Bilinmiyor",INDEX(Malzemeler!$G$5:$G$100,MATCH($B12,Malzemeler!$A$5:$A$100,0))),"Bilinmiyor")) | F12: =IF($B12="","",IFERROR(IF(INDEX(Malzemeler!$H$5:$H$100,MATCH($B12,Malzemeler!$A$5:$A$100,0))="","Bilinmiyor",INDEX(Malzemeler!$H$5:$H$100,MATCH($B12,Malzemeler!$A$5:$A$100,0))),"Bilinmiyor")) | G12: =IF($B12="","",IFERROR(IF(INDEX(Malzemeler!$I$5:$I$100,MATCH($B12,Malzemeler!$A$5:$A$100,0))="","Bilinmiyor",INDEX(Malzemeler!$I$5:$I$100,MATCH($B12,Malzemeler!$A$5:$A$100,0))),"Bilinmiyor")) | H12: =IF($B12="","",IFERROR(IF(INDEX(Malzemeler!$J$5:$J$100,MATCH($B12,Malzemeler!$A$5:$A$100,0))="","Bilinmiyor",INDEX(Malzemeler!$J$5:$J$100,MATCH($B12,Malzemeler!$A$5:$A$100,0))),"Bilinmiyor")) | I12: =IF($B12="","",IFERROR(IF(INDEX(Malzemeler!$K$5:$K$100,MATCH($B12,Malzemeler!$A$5:$A$100,0))="","Bilinmiyor",INDEX(Malzemeler!$K$5:$K$100,MATCH($B12,Malzemeler!$A$5:$A$100,0))),"Bilinmiyor")) | J12: =IF($B12="","",IFERROR(IF(INDEX(Malzemeler!$L$5:$L$100,MATCH($B12,Malzemeler!$A$5:$A$100,0))="","Bilinmiyor",INDEX(Malzemeler!$L$5:$L$100,MATCH($B12,Malzemeler!$A$5:$A$100,0))),"Bilinmiyor")) | K12: =IF($B12="","",IFERROR(IF(INDEX(Malzemeler!$M$5:$M$100,MATCH($B12,Malzemeler!$A$5:$A$100,0))="","Bilinmiyor",INDEX(Malzemeler!$M$5:$M$100,MATCH($B12,Malzemeler!$A$5:$A$100,0))),"Bilinmiyor")) | L12: =IF($B12="","",IFERROR(IF(INDEX(Malzemeler!$N$5:$N$100,MATCH($B12,Malzemeler!$A$5:$A$100,0))="","Bilinmiyor",INDEX(Malzemeler!$N$5:$N$100,MATCH($B12,Malzemeler!$A$5:$A$100,0))),"Bilinmiyor")) | M12: =IF($B12="","",IFERROR(IF(INDEX(Malzemeler!$O$5:$O$100,MATCH($B12,Malzemeler!$A$5:$A$100,0))="","Bilinmiyor",INDEX(Malzemeler!$O$5:$O$100,MATCH($B12,Malzemeler!$A$5:$A$100,0))),"Bilinmiyor")) | N12: =IF($B12="","",IFERROR(IF(INDEX(Malzemeler!$P$5:$P$100,MATCH($B12,Malzemeler!$A$5:$A$100,0))="","Bilinmiyor",INDEX(Malzemeler!$P$5:$P$100,MATCH($B12,Malzemeler!$A$5:$A$100,0))),"Bilinmiyor")) | O12: =IF($B12="","",IFERROR(IF(INDEX(Malzemeler!$Q$5:$Q$100,MATCH($B12,Malzemeler!$A$5:$A$100,0))="","Bilinmiyor",INDEX(Malzemeler!$Q$5:$Q$100,MATCH($B12,Malzemeler!$A$5:$A$100,0))),"Bilinmiyor")) | P12: =IF($B12="","",IFERROR(IF(INDEX(Malzemeler!$R$5:$R$100,MATCH($B12,Malzemeler!$A$5:$A$100,0))="","Bilinmiyor",INDEX(Malzemeler!$R$5:$R$100,MATCH($B12,Malzemeler!$A$5:$A$100,0))),"Bilinmiyor"))
A13: Örnek: Klasik Tavuk Burger | B13: Kızartma yağı | C13: =IF($B13="","",IFERROR(IF(INDEX(Malzemeler!$E$5:$E$100,MATCH($B13,Malzemeler!$A$5:$A$100,0))="","Bilinmiyor",INDEX(Malzemeler!$E$5:$E$100,MATCH($B13,Malzemeler!$A$5:$A$100,0))),"Bilinmiyor")) | D13: =IF($B13="","",IFERROR(IF(INDEX(Malzemeler!$F$5:$F$100,MATCH($B13,Malzemeler!$A$5:$A$100,0))="","Bilinmiyor",INDEX(Malzemeler!$F$5:$F$100,MATCH($B13,Malzemeler!$A$5:$A$100,0))),"Bilinmiyor")) | E13: =IF($B13="","",IFERROR(IF(INDEX(Malzemeler!$G$5:$G$100,MATCH($B13,Malzemeler!$A$5:$A$100,0))="","Bilinmiyor",INDEX(Malzemeler!$G$5:$G$100,MATCH($B13,Malzemeler!$A$5:$A$100,0))),"Bilinmiyor")) | F13: =IF($B13="","",IFERROR(IF(INDEX(Malzemeler!$H$5:$H$100,MATCH($B13,Malzemeler!$A$5:$A$100,0))="","Bilinmiyor",INDEX(Malzemeler!$H$5:$H$100,MATCH($B13,Malzemeler!$A$5:$A$100,0))),"Bilinmiyor")) | G13: =IF($B13="","",IFERROR(IF(INDEX(Malzemeler!$I$5:$I$100,MATCH($B13,Malzemeler!$A$5:$A$100,0))="","Bilinmiyor",INDEX(Malzemeler!$I$5:$I$100,MATCH($B13,Malzemeler!$A$5:$A$100,0))),"Bilinmiyor")) | H13: =IF($B13="","",IFERROR(IF(INDEX(Malzemeler!$J$5:$J$100,MATCH($B13,Malzemeler!$A$5:$A$100,0))="","Bilinmiyor",INDEX(Malzemeler!$J$5:$J$100,MATCH($B13,Malzemeler!$A$5:$A$100,0))),"Bilinmiyor")) | I13: =IF($B13="","",IFERROR(IF(INDEX(Malzemeler!$K$5:$K$100,MATCH($B13,Malzemeler!$A$5:$A$100,0))="","Bilinmiyor",INDEX(Malzemeler!$K$5:$K$100,MATCH($B13,Malzemeler!$A$5:$A$100,0))),"Bilinmiyor")) | J13: =IF($B13="","",IFERROR(IF(INDEX(Malzemeler!$L$5:$L$100,MATCH($B13,Malzemeler!$A$5:$A$100,0))="","Bilinmiyor",INDEX(Malzemeler!$L$5:$L$100,MATCH($B13,Malzemeler!$A$5:$A$100,0))),"Bilinmiyor")) | K13: =IF($B13="","",IFERROR(IF(INDEX(Malzemeler!$M$5:$M$100,MATCH($B13,Malzemeler!$A$5:$A$100,0))="","Bilinmiyor",INDEX(Malzemeler!$M$5:$M$100,MATCH($B13,Malzemeler!$A$5:$A$100,0))),"Bilinmiyor")) | L13: =IF($B13="","",IFERROR(IF(INDEX(Malzemeler!$N$5:$N$100,MATCH($B13,Malzemeler!$A$5:$A$100,0))="","Bilinmiyor",INDEX(Malzemeler!$N$5:$N$100,MATCH($B13,Malzemeler!$A$5:$A$100,0))),"Bilinmiyor")) | M13: =IF($B13="","",IFERROR(IF(INDEX(Malzemeler!$O$5:$O$100,MATCH($B13,Malzemeler!$A$5:$A$100,0))="","Bilinmiyor",INDEX(Malzemeler!$O$5:$O$100,MATCH($B13,Malzemeler!$A$5:$A$100,0))),"Bilinmiyor")) | N13: =IF($B13="","",IFERROR(IF(INDEX(Malzemeler!$P$5:$P$100,MATCH($B13,Malzemeler!$A$5:$A$100,0))="","Bilinmiyor",INDEX(Malzemeler!$P$5:$P$100,MATCH($B13,Malzemeler!$A$5:$A$100,0))),"Bilinmiyor")) | O13: =IF($B13="","",IFERROR(IF(INDEX(Malzemeler!$Q$5:$Q$100,MATCH($B13,Malzemeler!$A$5:$A$100,0))="","Bilinmiyor",INDEX(Malzemeler!$Q$5:$Q$100,MATCH($B13,Malzemeler!$A$5:$A$100,0))),"Bilinmiyor")) | P13: =IF($B13="","",IFERROR(IF(INDEX(Malzemeler!$R$5:$R$100,MATCH($B13,Malzemeler!$A$5:$A$100,0))="","Bilinmiyor",INDEX(Malzemeler!$R$5:$R$100,MATCH($B13,Malzemeler!$A$5:$A$100,0))),"Bilinmiyor"))
A14: Örnek: Nugget (6'lı) | B14: Hazır nugget / strips / şinitzel | C14: =IF($B14="","",IFERROR(IF(INDEX(Malzemeler!$E$5:$E$100,MATCH($B14,Malzemeler!$A$5:$A$100,0))="","Bilinmiyor",INDEX(Malzemeler!$E$5:$E$100,MATCH($B14,Malzemeler!$A$5:$A$100,0))),"Bilinmiyor")) | D14: =IF($B14="","",IFERROR(IF(INDEX(Malzemeler!$F$5:$F$100,MATCH($B14,Malzemeler!$A$5:$A$100,0))="","Bilinmiyor",INDEX(Malzemeler!$F$5:$F$100,MATCH($B14,Malzemeler!$A$5:$A$100,0))),"Bilinmiyor")) | E14: =IF($B14="","",IFERROR(IF(INDEX(Malzemeler!$G$5:$G$100,MATCH($B14,Malzemeler!$A$5:$A$100,0))="","Bilinmiyor",INDEX(Malzemeler!$G$5:$G$100,MATCH($B14,Malzemeler!$A$5:$A$100,0))),"Bilinmiyor")) | F14: =IF($B14="","",IFERROR(IF(INDEX(Malzemeler!$H$5:$H$100,MATCH($B14,Malzemeler!$A$5:$A$100,0))="","Bilinmiyor",INDEX(Malzemeler!$H$5:$H$100,MATCH($B14,Malzemeler!$A$5:$A$100,0))),"Bilinmiyor")) | G14: =IF($B14="","",IFERROR(IF(INDEX(Malzemeler!$I$5:$I$100,MATCH($B14,Malzemeler!$A$5:$A$100,0))="","Bilinmiyor",INDEX(Malzemeler!$I$5:$I$100,MATCH($B14,Malzemeler!$A$5:$A$100,0))),"Bilinmiyor")) | H14: =IF($B14="","",IFERROR(IF(INDEX(Malzemeler!$J$5:$J$100,MATCH($B14,Malzemeler!$A$5:$A$100,0))="","Bilinmiyor",INDEX(Malzemeler!$J$5:$J$100,MATCH($B14,Malzemeler!$A$5:$A$100,0))),"Bilinmiyor")) | I14: =IF($B14="","",IFERROR(IF(INDEX(Malzemeler!$K$5:$K$100,MATCH($B14,Malzemeler!$A$5:$A$100,0))="","Bilinmiyor",INDEX(Malzemeler!$K$5:$K$100,MATCH($B14,Malzemeler!$A$5:$A$100,0))),"Bilinmiyor")) | J14: =IF($B14="","",IFERROR(IF(INDEX(Malzemeler!$L$5:$L$100,MATCH($B14,Malzemeler!$A$5:$A$100,0))="","Bilinmiyor",INDEX(Malzemeler!$L$5:$L$100,MATCH($B14,Malzemeler!$A$5:$A$100,0))),"Bilinmiyor")) | K14: =IF($B14="","",IFERROR(IF(INDEX(Malzemeler!$M$5:$M$100,MATCH($B14,Malzemeler!$A$5:$A$100,0))="","Bilinmiyor",INDEX(Malzemeler!$M$5:$M$100,MATCH($B14,Malzemeler!$A$5:$A$100,0))),"Bilinmiyor")) | L14: =IF($B14="","",IFERROR(IF(INDEX(Malzemeler!$N$5:$N$100,MATCH($B14,Malzemeler!$A$5:$A$100,0))="","Bilinmiyor",INDEX(Malzemeler!$N$5:$N$100,MATCH($B14,Malzemeler!$A$5:$A$100,0))),"Bilinmiyor")) | M14: =IF($B14="","",IFERROR(IF(INDEX(Malzemeler!$O$5:$O$100,MATCH($B14,Malzemeler!$A$5:$A$100,0))="","Bilinmiyor",INDEX(Malzemeler!$O$5:$O$100,MATCH($B14,Malzemeler!$A$5:$A$100,0))),"Bilinmiyor")) | N14: =IF($B14="","",IFERROR(IF(INDEX(Malzemeler!$P$5:$P$100,MATCH($B14,Malzemeler!$A$5:$A$100,0))="","Bilinmiyor",INDEX(Malzemeler!$P$5:$P$100,MATCH($B14,Malzemeler!$A$5:$A$100,0))),"Bilinmiyor")) | O14: =IF($B14="","",IFERROR(IF(INDEX(Malzemeler!$Q$5:$Q$100,MATCH($B14,Malzemeler!$A$5:$A$100,0))="","Bilinmiyor",INDEX(Malzemeler!$Q$5:$Q$100,MATCH($B14,Malzemeler!$A$5:$A$100,0))),"Bilinmiyor")) | P14: =IF($B14="","",IFERROR(IF(INDEX(Malzemeler!$R$5:$R$100,MATCH($B14,Malzemeler!$A$5:$A$100,0))="","Bilinmiyor",INDEX(Malzemeler!$R$5:$R$100,MATCH($B14,Malzemeler!$A$5:$A$100,0))),"Bilinmiyor"))
A15: Örnek: Nugget (6'lı) | B15: Kızartma yağı | C15: =IF($B15="","",IFERROR(IF(INDEX(Malzemeler!$E$5:$E$100,MATCH($B15,Malzemeler!$A$5:$A$100,0))="","Bilinmiyor",INDEX(Malzemeler!$E$5:$E$100,MATCH($B15,Malzemeler!$A$5:$A$100,0))),"Bilinmiyor")) | D15: =IF($B15="","",IFERROR(IF(INDEX(Malzemeler!$F$5:$F$100,MATCH($B15,Malzemeler!$A$5:$A$100,0))="","Bilinmiyor",INDEX(Malzemeler!$F$5:$F$100,MATCH($B15,Malzemeler!$A$5:$A$100,0))),"Bilinmiyor")) | E15: =IF($B15="","",IFERROR(IF(INDEX(Malzemeler!$G$5:$G$100,MATCH($B15,Malzemeler!$A$5:$A$100,0))="","Bilinmiyor",INDEX(Malzemeler!$G$5:$G$100,MATCH($B15,Malzemeler!$A$5:$A$100,0))),"Bilinmiyor")) | F15: =IF($B15="","",IFERROR(IF(INDEX(Malzemeler!$H$5:$H$100,MATCH($B15,Malzemeler!$A$5:$A$100,0))="","Bilinmiyor",INDEX(Malzemeler!$H$5:$H$100,MATCH($B15,Malzemeler!$A$5:$A$100,0))),"Bilinmiyor")) | G15: =IF($B15="","",IFERROR(IF(INDEX(Malzemeler!$I$5:$I$100,MATCH($B15,Malzemeler!$A$5:$A$100,0))="","Bilinmiyor",INDEX(Malzemeler!$I$5:$I$100,MATCH($B15,Malzemeler!$A$5:$A$100,0))),"Bilinmiyor")) | H15: =IF($B15="","",IFERROR(IF(INDEX(Malzemeler!$J$5:$J$100,MATCH($B15,Malzemeler!$A$5:$A$100,0))="","Bilinmiyor",INDEX(Malzemeler!$J$5:$J$100,MATCH($B15,Malzemeler!$A$5:$A$100,0))),"Bilinmiyor")) | I15: =IF($B15="","",IFERROR(IF(INDEX(Malzemeler!$K$5:$K$100,MATCH($B15,Malzemeler!$A$5:$A$100,0))="","Bilinmiyor",INDEX(Malzemeler!$K$5:$K$100,MATCH($B15,Malzemeler!$A$5:$A$100,0))),"Bilinmiyor")) | J15: =IF($B15="","",IFERROR(IF(INDEX(Malzemeler!$L$5:$L$100,MATCH($B15,Malzemeler!$A$5:$A$100,0))="","Bilinmiyor",INDEX(Malzemeler!$L$5:$L$100,MATCH($B15,Malzemeler!$A$5:$A$100,0))),"Bilinmiyor")) | K15: =IF($B15="","",IFERROR(IF(INDEX(Malzemeler!$M$5:$M$100,MATCH($B15,Malzemeler!$A$5:$A$100,0))="","Bilinmiyor",INDEX(Malzemeler!$M$5:$M$100,MATCH($B15,Malzemeler!$A$5:$A$100,0))),"Bilinmiyor")) | L15: =IF($B15="","",IFERROR(IF(INDEX(Malzemeler!$N$5:$N$100,MATCH($B15,Malzemeler!$A$5:$A$100,0))="","Bilinmiyor",INDEX(Malzemeler!$N$5:$N$100,MATCH($B15,Malzemeler!$A$5:$A$100,0))),"Bilinmiyor")) | M15: =IF($B15="","",IFERROR(IF(INDEX(Malzemeler!$O$5:$O$100,MATCH($B15,Malzemeler!$A$5:$A$100,0))="","Bilinmiyor",INDEX(Malzemeler!$O$5:$O$100,MATCH($B15,Malzemeler!$A$5:$A$100,0))),"Bilinmiyor")) | N15: =IF($B15="","",IFERROR(IF(INDEX(Malzemeler!$P$5:$P$100,MATCH($B15,Malzemeler!$A$5:$A$100,0))="","Bilinmiyor",INDEX(Malzemeler!$P$5:$P$100,MATCH($B15,Malzemeler!$A$5:$A$100,0))),"Bilinmiyor")) | O15: =IF($B15="","",IFERROR(IF(INDEX(Malzemeler!$Q$5:$Q$100,MATCH($B15,Malzemeler!$A$5:$A$100,0))="","Bilinmiyor",INDEX(Malzemeler!$Q$5:$Q$100,MATCH($B15,Malzemeler!$A$5:$A$100,0))),"Bilinmiyor")) | P15: =IF($B15="","",IFERROR(IF(INDEX(Malzemeler!$R$5:$R$100,MATCH($B15,Malzemeler!$A$5:$A$100,0))="","Bilinmiyor",INDEX(Malzemeler!$R$5:$R$100,MATCH($B15,Malzemeler!$A$5:$A$100,0))),"Bilinmiyor"))
A16: Örnek: Patates Kızartması | B16: Patates kızartması (dondurulmuş) | C16: =IF($B16="","",IFERROR(IF(INDEX(Malzemeler!$E$5:$E$100,MATCH($B16,Malzemeler!$A$5:$A$100,0))="","Bilinmiyor",INDEX(Malzemeler!$E$5:$E$100,MATCH($B16,Malzemeler!$A$5:$A$100,0))),"Bilinmiyor")) | D16: =IF($B16="","",IFERROR(IF(INDEX(Malzemeler!$F$5:$F$100,MATCH($B16,Malzemeler!$A$5:$A$100,0))="","Bilinmiyor",INDEX(Malzemeler!$F$5:$F$100,MATCH($B16,Malzemeler!$A$5:$A$100,0))),"Bilinmiyor")) | E16: =IF($B16="","",IFERROR(IF(INDEX(Malzemeler!$G$5:$G$100,MATCH($B16,Malzemeler!$A$5:$A$100,0))="","Bilinmiyor",INDEX(Malzemeler!$G$5:$G$100,MATCH($B16,Malzemeler!$A$5:$A$100,0))),"Bilinmiyor")) | F16: =IF($B16="","",IFERROR(IF(INDEX(Malzemeler!$H$5:$H$100,MATCH($B16,Malzemeler!$A$5:$A$100,0))="","Bilinmiyor",INDEX(Malzemeler!$H$5:$H$100,MATCH($B16,Malzemeler!$A$5:$A$100,0))),"Bilinmiyor")) | G16: =IF($B16="","",IFERROR(IF(INDEX(Malzemeler!$I$5:$I$100,MATCH($B16,Malzemeler!$A$5:$A$100,0))="","Bilinmiyor",INDEX(Malzemeler!$I$5:$I$100,MATCH($B16,Malzemeler!$A$5:$A$100,0))),"Bilinmiyor")) | H16: =IF($B16="","",IFERROR(IF(INDEX(Malzemeler!$J$5:$J$100,MATCH($B16,Malzemeler!$A$5:$A$100,0))="","Bilinmiyor",INDEX(Malzemeler!$J$5:$J$100,MATCH($B16,Malzemeler!$A$5:$A$100,0))),"Bilinmiyor")) | I16: =IF($B16="","",IFERROR(IF(INDEX(Malzemeler!$K$5:$K$100,MATCH($B16,Malzemeler!$A$5:$A$100,0))="","Bilinmiyor",INDEX(Malzemeler!$K$5:$K$100,MATCH($B16,Malzemeler!$A$5:$A$100,0))),"Bilinmiyor")) | J16: =IF($B16="","",IFERROR(IF(INDEX(Malzemeler!$L$5:$L$100,MATCH($B16,Malzemeler!$A$5:$A$100,0))="","Bilinmiyor",INDEX(Malzemeler!$L$5:$L$100,MATCH($B16,Malzemeler!$A$5:$A$100,0))),"Bilinmiyor")) | K16: =IF($B16="","",IFERROR(IF(INDEX(Malzemeler!$M$5:$M$100,MATCH($B16,Malzemeler!$A$5:$A$100,0))="","Bilinmiyor",INDEX(Malzemeler!$M$5:$M$100,MATCH($B16,Malzemeler!$A$5:$A$100,0))),"Bilinmiyor")) | L16: =IF($B16="","",IFERROR(IF(INDEX(Malzemeler!$N$5:$N$100,MATCH($B16,Malzemeler!$A$5:$A$100,0))="","Bilinmiyor",INDEX(Malzemeler!$N$5:$N$100,MATCH($B16,Malzemeler!$A$5:$A$100,0))),"Bilinmiyor")) | M16: =IF($B16="","",IFERROR(IF(INDEX(Malzemeler!$O$5:$O$100,MATCH($B16,Malzemeler!$A$5:$A$100,0))="","Bilinmiyor",INDEX(Malzemeler!$O$5:$O$100,MATCH($B16,Malzemeler!$A$5:$A$100,0))),"Bilinmiyor")) | N16: =IF($B16="","",IFERROR(IF(INDEX(Malzemeler!$P$5:$P$100,MATCH($B16,Malzemeler!$A$5:$A$100,0))="","Bilinmiyor",INDEX(Malzemeler!$P$5:$P$100,MATCH($B16,Malzemeler!$A$5:$A$100,0))),"Bilinmiyor")) | O16: =IF($B16="","",IFERROR(IF(INDEX(Malzemeler!$Q$5:$Q$100,MATCH($B16,Malzemeler!$A$5:$A$100,0))="","Bilinmiyor",INDEX(Malzemeler!$Q$5:$Q$100,MATCH($B16,Malzemeler!$A$5:$A$100,0))),"Bilinmiyor")) | P16: =IF($B16="","",IFERROR(IF(INDEX(Malzemeler!$R$5:$R$100,MATCH($B16,Malzemeler!$A$5:$A$100,0))="","Bilinmiyor",INDEX(Malzemeler!$R$5:$R$100,MATCH($B16,Malzemeler!$A$5:$A$100,0))),"Bilinmiyor"))
... A18: Örnek: Patates Kızartması | B18: Kızartma yağı | C18: =IF($B18="","",IFERROR(IF(INDEX(Malzemeler!$E$5:$E$100,MATCH($B18,Malzemeler!$A$5:$A$100,0))="","Bilinmiyor",INDEX(Malzemeler!$E$5:$E$100,MATCH($B18,Malzemeler!$A$5:$A$100,0))),"Bilinmiyor")) | D18: =IF($B18="","",IFERROR(IF(INDEX(Malzemeler!$F$5:$F$100,MATCH($B18,Malzemeler!$A$5:$A$100,0))="","Bilinmiyor",INDEX(Malzemeler!$F$5:$F$100,MATCH($B18,Malzemeler!$A$5:$A$100,0))),"Bilinmiyor")) | E18: =IF($B18="","",IFERROR(IF(INDEX(Malzemeler!$G$5:$G$100,MATCH($B18,Malzemeler!$A$5:$A$100,0))="","Bilinmiyor",INDEX(Malzemeler!$G$5:$G$100,MATCH($B18,Malzemeler!$A$5:$A$100,0))),"Bilinmiyor")) | F18: =IF($B18="","",IFERROR(IF(INDEX(Malzemeler!$H$5:$H$100,MATCH($B18,Malzemeler!$A$5:$A$100,0))="","Bilinmiyor",INDEX(Malzemeler!$H$5:$H$100,MATCH($B18,Malzemeler!$A$5:$A$100,0))),"Bilinmiyor")) | G18: =IF($B18="","",IFERROR(IF(INDEX(Malzemeler!$I$5:$I$100,MATCH($B18,Malzemeler!$A$5:$A$100,0))="","Bilinmiyor",INDEX(Malzemeler!$I$5:$I$100,MATCH($B18,Malzemeler!$A$5:$A$100,0))),"Bilinmiyor")) | H18: =IF($B18="","",IFERROR(IF(INDEX(Malzemeler!$J$5:$J$100,MATCH($B18,Malzemeler!$A$5:$A$100,0))="","Bilinmiyor",INDEX(Malzemeler!$J$5:$J$100,MATCH($B18,Malzemeler!$A$5:$A$100,0))),"Bilinmiyor")) | I18: =IF($B18="","",IFERROR(IF(INDEX(Malzemeler!$K$5:$K$100,MATCH($B18,Malzemeler!$A$5:$A$100,0))="","Bilinmiyor",INDEX(Malzemeler!$K$5:$K$100,MATCH($B18,Malzemeler!$A$5:$A$100,0))),"Bilinmiyor")) | J18: =IF($B18="","",IFERROR(IF(INDEX(Malzemeler!$L$5:$L$100,MATCH($B18,Malzemeler!$A$5:$A$100,0))="","Bilinmiyor",INDEX(Malzemeler!$L$5:$L$100,MATCH($B18,Malzemeler!$A$5:$A$100,0))),"Bilinmiyor")) | K18: =IF($B18="","",IFERROR(IF(INDEX(Malzemeler!$M$5:$M$100,MATCH($B18,Malzemeler!$A$5:$A$100,0))="","Bilinmiyor",INDEX(Malzemeler!$M$5:$M$100,MATCH($B18,Malzemeler!$A$5:$A$100,0))),"Bilinmiyor")) | L18: =IF($B18="","",IFERROR(IF(INDEX(Malzemeler!$N$5:$N$100,MATCH($B18,Malzemeler!$A$5:$A$100,0))="","Bilinmiyor",INDEX(Malzemeler!$N$5:$N$100,MATCH($B18,Malzemeler!$A$5:$A$100,0))),"Bilinmiyor")) | M18: =IF($B18="","",IFERROR(IF(INDEX(Malzemeler!$O$5:$O$100,MATCH($B18,Malzemeler!$A$5:$A$100,0))="","Bilinmiyor",INDEX(Malzemeler!$O$5:$O$100,MATCH($B18,Malzemeler!$A$5:$A$100,0))),"Bilinmiyor")) | N18: =IF($B18="","",IFERROR(IF(INDEX(Malzemeler!$P$5:$P$100,MATCH($B18,Malzemeler!$A$5:$A$100,0))="","Bilinmiyor",INDEX(Malzemeler!$P$5:$P$100,MATCH($B18,Malzemeler!$A$5:$A$100,0))),"Bilinmiyor")) | O18: =IF($B18="","",IFERROR(IF(INDEX(Malzemeler!$Q$5:$Q$100,MATCH($B18,Malzemeler!$A$5:$A$100,0))="","Bilinmiyor",INDEX(Malzemeler!$Q$5:$Q$100,MATCH($B18,Malzemeler!$A$5:$A$100,0))),"Bilinmiyor")) | P18: =IF($B18="","",IFERROR(IF(INDEX(Malzemeler!$R$5:$R$100,MATCH($B18,Malzemeler!$A$5:$A$100,0))="","Bilinmiyor",INDEX(Malzemeler!$R$5:$R$100,MATCH($B18,Malzemeler!$A$5:$A$100,0))),"Bilinmiyor"))
C19: =IF($B19="","",IFERROR(IF(INDEX(Malzemeler!$E$5:$E$100,MATCH($B19,Malzemeler!$A$5:$A$100,0))="","Bilinmiyor",INDEX(Malzemeler!$E$5:$E$100,MATCH($B19,Malzemeler!$A$5:$A$100,0))),"Bilinmiyor")) | D19: =IF($B19="","",IFERROR(IF(INDEX(Malzemeler!$F$5:$F$100,MATCH($B19,Malzemeler!$A$5:$A$100,0))="","Bilinmiyor",INDEX(Malzemeler!$F$5:$F$100,MATCH($B19,Malzemeler!$A$5:$A$100,0))),"Bilinmiyor")) | E19: =IF($B19="","",IFERROR(IF(INDEX(Malzemeler!$G$5:$G$100,MATCH($B19,Malzemeler!$A$5:$A$100,0))="","Bilinmiyor",INDEX(Malzemeler!$G$5:$G$100,MATCH($B19,Malzemeler!$A$5:$A$100,0))),"Bilinmiyor")) | F19: =IF($B19="","",IFERROR(IF(INDEX(Malzemeler!$H$5:$H$100,MATCH($B19,Malzemeler!$A$5:$A$100,0))="","Bilinmiyor",INDEX(Malzemeler!$H$5:$H$100,MATCH($B19,Malzemeler!$A$5:$A$100,0))),"Bilinmiyor")) | G19: =IF($B19="","",IFERROR(IF(INDEX(Malzemeler!$I$5:$I$100,MATCH($B19,Malzemeler!$A$5:$A$100,0))="","Bilinmiyor",INDEX(Malzemeler!$I$5:$I$100,MATCH($B19,Malzemeler!$A$5:$A$100,0))),"Bilinmiyor")) | H19: =IF($B19="","",IFERROR(IF(INDEX(Malzemeler!$J$5:$J$100,MATCH($B19,Malzemeler!$A$5:$A$100,0))="","Bilinmiyor",INDEX(Malzemeler!$J$5:$J$100,MATCH($B19,Malzemeler!$A$5:$A$100,0))),"Bilinmiyor")) | I19: =IF($B19="","",IFERROR(IF(INDEX(Malzemeler!$K$5:$K$100,MATCH($B19,Malzemeler!$A$5:$A$100,0))="","Bilinmiyor",INDEX(Malzemeler!$K$5:$K$100,MATCH($B19,Malzemeler!$A$5:$A$100,0))),"Bilinmiyor")) | J19: =IF($B19="","",IFERROR(IF(INDEX(Malzemeler!$L$5:$L$100,MATCH($B19,Malzemeler!$A$5:$A$100,0))="","Bilinmiyor",INDEX(Malzemeler!$L$5:$L$100,MATCH($B19,Malzemeler!$A$5:$A$100,0))),"Bilinmiyor")) | K19: =IF($B19="","",IFERROR(IF(INDEX(Malzemeler!$M$5:$M$100,MATCH($B19,Malzemeler!$A$5:$A$100,0))="","Bilinmiyor",INDEX(Malzemeler!$M$5:$M$100,MATCH($B19,Malzemeler!$A$5:$A$100,0))),"Bilinmiyor")) | L19: =IF($B19="","",IFERROR(IF(INDEX(Malzemeler!$N$5:$N$100,MATCH($B19,Malzemeler!$A$5:$A$100,0))="","Bilinmiyor",INDEX(Malzemeler!$N$5:$N$100,MATCH($B19,Malzemeler!$A$5:$A$100,0))),"Bilinmiyor")) | M19: =IF($B19="","",IFERROR(IF(INDEX(Malzemeler!$O$5:$O$100,MATCH($B19,Malzemeler!$A$5:$A$100,0))="","Bilinmiyor",INDEX(Malzemeler!$O$5:$O$100,MATCH($B19,Malzemeler!$A$5:$A$100,0))),"Bilinmiyor")) | N19: =IF($B19="","",IFERROR(IF(INDEX(Malzemeler!$P$5:$P$100,MATCH($B19,Malzemeler!$A$5:$A$100,0))="","Bilinmiyor",INDEX(Malzemeler!$P$5:$P$100,MATCH($B19,Malzemeler!$A$5:$A$100,0))),"Bilinmiyor")) | O19: =IF($B19="","",IFERROR(IF(INDEX(Malzemeler!$Q$5:$Q$100,MATCH($B19,Malzemeler!$A$5:$A$100,0))="","Bilinmiyor",INDEX(Malzemeler!$Q$5:$Q$100,MATCH($B19,Malzemeler!$A$5:$A$100,0))),"Bilinmiyor")) | P19: =IF($B19="","",IFERROR(IF(INDEX(Malzemeler!$R$5:$R$100,MATCH($B19,Malzemeler!$A$5:$A$100,0))="","Bilinmiyor",INDEX(Malzemeler!$R$5:$R$100,MATCH($B19,Malzemeler!$A$5:$A$100,0))),"Bilinmiyor"))
C20: =IF($B20="","",IFERROR(IF(INDEX(Malzemeler!$E$5:$E$100,MATCH($B20,Malzemeler!$A$5:$A$100,0))="","Bilinmiyor",INDEX(Malzemeler!$E$5:$E$100,MATCH($B20,Malzemeler!$A$5:$A$100,0))),"Bilinmiyor")) | D20: =IF($B20="","",IFERROR(IF(INDEX(Malzemeler!$F$5:$F$100,MATCH($B20,Malzemeler!$A$5:$A$100,0))="","Bilinmiyor",INDEX(Malzemeler!$F$5:$F$100,MATCH($B20,Malzemeler!$A$5:$A$100,0))),"Bilinmiyor")) | E20: =IF($B20="","",IFERROR(IF(INDEX(Malzemeler!$G$5:$G$100,MATCH($B20,Malzemeler!$A$5:$A$100,0))="","Bilinmiyor",INDEX(Malzemeler!$G$5:$G$100,MATCH($B20,Malzemeler!$A$5:$A$100,0))),"Bilinmiyor")) | F20: =IF($B20="","",IFERROR(IF(INDEX(Malzemeler!$H$5:$H$100,MATCH($B20,Malzemeler!$A$5:$A$100,0))="","Bilinmiyor",INDEX(Malzemeler!$H$5:$H$100,MATCH($B20,Malzemeler!$A$5:$A$100,0))),"Bilinmiyor")) | G20: =IF($B20="","",IFERROR(IF(INDEX(Malzemeler!$I$5:$I$100,MATCH($B20,Malzemeler!$A$5:$A$100,0))="","Bilinmiyor",INDEX(Malzemeler!$I$5:$I$100,MATCH($B20,Malzemeler!$A$5:$A$100,0))),"Bilinmiyor")) | H20: =IF($B20="","",IFERROR(IF(INDEX(Malzemeler!$J$5:$J$100,MATCH($B20,Malzemeler!$A$5:$A$100,0))="","Bilinmiyor",INDEX(Malzemeler!$J$5:$J$100,MATCH($B20,Malzemeler!$A$5:$A$100,0))),"Bilinmiyor")) | I20: =IF($B20="","",IFERROR(IF(INDEX(Malzemeler!$K$5:$K$100,MATCH($B20,Malzemeler!$A$5:$A$100,0))="","Bilinmiyor",INDEX(Malzemeler!$K$5:$K$100,MATCH($B20,Malzemeler!$A$5:$A$100,0))),"Bilinmiyor")) | J20: =IF($B20="","",IFERROR(IF(INDEX(Malzemeler!$L$5:$L$100,MATCH($B20,Malzemeler!$A$5:$A$100,0))="","Bilinmiyor",INDEX(Malzemeler!$L$5:$L$100,MATCH($B20,Malzemeler!$A$5:$A$100,0))),"Bilinmiyor")) | K20: =IF($B20="","",IFERROR(IF(INDEX(Malzemeler!$M$5:$M$100,MATCH($B20,Malzemeler!$A$5:$A$100,0))="","Bilinmiyor",INDEX(Malzemeler!$M$5:$M$100,MATCH($B20,Malzemeler!$A$5:$A$100,0))),"Bilinmiyor")) | L20: =IF($B20="","",IFERROR(IF(INDEX(Malzemeler!$N$5:$N$100,MATCH($B20,Malzemeler!$A$5:$A$100,0))="","Bilinmiyor",INDEX(Malzemeler!$N$5:$N$100,MATCH($B20,Malzemeler!$A$5:$A$100,0))),"Bilinmiyor")) | M20: =IF($B20="","",IFERROR(IF(INDEX(Malzemeler!$O$5:$O$100,MATCH($B20,Malzemeler!$A$5:$A$100,0))="","Bilinmiyor",INDEX(Malzemeler!$O$5:$O$100,MATCH($B20,Malzemeler!$A$5:$A$100,0))),"Bilinmiyor")) | N20: =IF($B20="","",IFERROR(IF(INDEX(Malzemeler!$P$5:$P$100,MATCH($B20,Malzemeler!$A$5:$A$100,0))="","Bilinmiyor",INDEX(Malzemeler!$P$5:$P$100,MATCH($B20,Malzemeler!$A$5:$A$100,0))),"Bilinmiyor")) | O20: =IF($B20="","",IFERROR(IF(INDEX(Malzemeler!$Q$5:$Q$100,MATCH($B20,Malzemeler!$A$5:$A$100,0))="","Bilinmiyor",INDEX(Malzemeler!$Q$5:$Q$100,MATCH($B20,Malzemeler!$A$5:$A$100,0))),"Bilinmiyor")) | P20: =IF($B20="","",IFERROR(IF(INDEX(Malzemeler!$R$5:$R$100,MATCH($B20,Malzemeler!$A$5:$A$100,0))="","Bilinmiyor",INDEX(Malzemeler!$R$5:$R$100,MATCH($B20,Malzemeler!$A$5:$A$100,0))),"Bilinmiyor"))
C21: =IF($B21="","",IFERROR(IF(INDEX(Malzemeler!$E$5:$E$100,MATCH($B21,Malzemeler!$A$5:$A$100,0))="","Bilinmiyor",INDEX(Malzemeler!$E$5:$E$100,MATCH($B21,Malzemeler!$A$5:$A$100,0))),"Bilinmiyor")) | D21: =IF($B21="","",IFERROR(IF(INDEX(Malzemeler!$F$5:$F$100,MATCH($B21,Malzemeler!$A$5:$A$100,0))="","Bilinmiyor",INDEX(Malzemeler!$F$5:$F$100,MATCH($B21,Malzemeler!$A$5:$A$100,0))),"Bilinmiyor")) | E21: =IF($B21="","",IFERROR(IF(INDEX(Malzemeler!$G$5:$G$100,MATCH($B21,Malzemeler!$A$5:$A$100,0))="","Bilinmiyor",INDEX(Malzemeler!$G$5:$G$100,MATCH($B21,Malzemeler!$A$5:$A$100,0))),"Bilinmiyor")) | F21: =IF($B21="","",IFERROR(IF(INDEX(Malzemeler!$H$5:$H$100,MATCH($B21,Malzemeler!$A$5:$A$100,0))="","Bilinmiyor",INDEX(Malzemeler!$H$5:$H$100,MATCH($B21,Malzemeler!$A$5:$A$100,0))),"Bilinmiyor")) | G21: =IF($B21="","",IFERROR(IF(INDEX(Malzemeler!$I$5:$I$100,MATCH($B21,Malzemeler!$A$5:$A$100,0))="","Bilinmiyor",INDEX(Malzemeler!$I$5:$I$100,MATCH($B21,Malzemeler!$A$5:$A$100,0))),"Bilinmiyor")) | H21: =IF($B21="","",IFERROR(IF(INDEX(Malzemeler!$J$5:$J$100,MATCH($B21,Malzemeler!$A$5:$A$100,0))="","Bilinmiyor",INDEX(Malzemeler!$J$5:$J$100,MATCH($B21,Malzemeler!$A$5:$A$100,0))),"Bilinmiyor")) | I21: =IF($B21="","",IFERROR(IF(INDEX(Malzemeler!$K$5:$K$100,MATCH($B21,Malzemeler!$A$5:$A$100,0))="","Bilinmiyor",INDEX(Malzemeler!$K$5:$K$100,MATCH($B21,Malzemeler!$A$5:$A$100,0))),"Bilinmiyor")) | J21: =IF($B21="","",IFERROR(IF(INDEX(Malzemeler!$L$5:$L$100,MATCH($B21,Malzemeler!$A$5:$A$100,0))="","Bilinmiyor",INDEX(Malzemeler!$L$5:$L$100,MATCH($B21,Malzemeler!$A$5:$A$100,0))),"Bilinmiyor")) | K21: =IF($B21="","",IFERROR(IF(INDEX(Malzemeler!$M$5:$M$100,MATCH($B21,Malzemeler!$A$5:$A$100,0))="","Bilinmiyor",INDEX(Malzemeler!$M$5:$M$100,MATCH($B21,Malzemeler!$A$5:$A$100,0))),"Bilinmiyor")) | L21: =IF($B21="","",IFERROR(IF(INDEX(Malzemeler!$N$5:$N$100,MATCH($B21,Malzemeler!$A$5:$A$100,0))="","Bilinmiyor",INDEX(Malzemeler!$N$5:$N$100,MATCH($B21,Malzemeler!$A$5:$A$100,0))),"Bilinmiyor")) | M21: =IF($B21="","",IFERROR(IF(INDEX(Malzemeler!$O$5:$O$100,MATCH($B21,Malzemeler!$A$5:$A$100,0))="","Bilinmiyor",INDEX(Malzemeler!$O$5:$O$100,MATCH($B21,Malzemeler!$A$5:$A$100,0))),"Bilinmiyor")) | N21: =IF($B21="","",IFERROR(IF(INDEX(Malzemeler!$P$5:$P$100,MATCH($B21,Malzemeler!$A$5:$A$100,0))="","Bilinmiyor",INDEX(Malzemeler!$P$5:$P$100,MATCH($B21,Malzemeler!$A$5:$A$100,0))),"Bilinmiyor")) | O21: =IF($B21="","",IFERROR(IF(INDEX(Malzemeler!$Q$5:$Q$100,MATCH($B21,Malzemeler!$A$5:$A$100,0))="","Bilinmiyor",INDEX(Malzemeler!$Q$5:$Q$100,MATCH($B21,Malzemeler!$A$5:$A$100,0))),"Bilinmiyor")) | P21: =IF($B21="","",IFERROR(IF(INDEX(Malzemeler!$R$5:$R$100,MATCH($B21,Malzemeler!$A$5:$A$100,0))="","Bilinmiyor",INDEX(Malzemeler!$R$5:$R$100,MATCH($B21,Malzemeler!$A$5:$A$100,0))),"Bilinmiyor"))
C22: =IF($B22="","",IFERROR(IF(INDEX(Malzemeler!$E$5:$E$100,MATCH($B22,Malzemeler!$A$5:$A$100,0))="","Bilinmiyor",INDEX(Malzemeler!$E$5:$E$100,MATCH($B22,Malzemeler!$A$5:$A$100,0))),"Bilinmiyor")) | D22: =IF($B22="","",IFERROR(IF(INDEX(Malzemeler!$F$5:$F$100,MATCH($B22,Malzemeler!$A$5:$A$100,0))="","Bilinmiyor",INDEX(Malzemeler!$F$5:$F$100,MATCH($B22,Malzemeler!$A$5:$A$100,0))),"Bilinmiyor")) | E22: =IF($B22="","",IFERROR(IF(INDEX(Malzemeler!$G$5:$G$100,MATCH($B22,Malzemeler!$A$5:$A$100,0))="","Bilinmiyor",INDEX(Malzemeler!$G$5:$G$100,MATCH($B22,Malzemeler!$A$5:$A$100,0))),"Bilinmiyor")) | F22: =IF($B22="","",IFERROR(IF(INDEX(Malzemeler!$H$5:$H$100,MATCH($B22,Malzemeler!$A$5:$A$100,0))="","Bilinmiyor",INDEX(Malzemeler!$H$5:$H$100,MATCH($B22,Malzemeler!$A$5:$A$100,0))),"Bilinmiyor")) | G22: =IF($B22="","",IFERROR(IF(INDEX(Malzemeler!$I$5:$I$100,MATCH($B22,Malzemeler!$A$5:$A$100,0))="","Bilinmiyor",INDEX(Malzemeler!$I$5:$I$100,MATCH($B22,Malzemeler!$A$5:$A$100,0))),"Bilinmiyor")) | H22: =IF($B22="","",IFERROR(IF(INDEX(Malzemeler!$J$5:$J$100,MATCH($B22,Malzemeler!$A$5:$A$100,0))="","Bilinmiyor",INDEX(Malzemeler!$J$5:$J$100,MATCH($B22,Malzemeler!$A$5:$A$100,0))),"Bilinmiyor")) | I22: =IF($B22="","",IFERROR(IF(INDEX(Malzemeler!$K$5:$K$100,MATCH($B22,Malzemeler!$A$5:$A$100,0))="","Bilinmiyor",INDEX(Malzemeler!$K$5:$K$100,MATCH($B22,Malzemeler!$A$5:$A$100,0))),"Bilinmiyor")) | J22: =IF($B22="","",IFERROR(IF(INDEX(Malzemeler!$L$5:$L$100,MATCH($B22,Malzemeler!$A$5:$A$100,0))="","Bilinmiyor",INDEX(Malzemeler!$L$5:$L$100,MATCH($B22,Malzemeler!$A$5:$A$100,0))),"Bilinmiyor")) | K22: =IF($B22="","",IFERROR(IF(INDEX(Malzemeler!$M$5:$M$100,MATCH($B22,Malzemeler!$A$5:$A$100,0))="","Bilinmiyor",INDEX(Malzemeler!$M$5:$M$100,MATCH($B22,Malzemeler!$A$5:$A$100,0))),"Bilinmiyor")) | L22: =IF($B22="","",IFERROR(IF(INDEX(Malzemeler!$N$5:$N$100,MATCH($B22,Malzemeler!$A$5:$A$100,0))="","Bilinmiyor",INDEX(Malzemeler!$N$5:$N$100,MATCH($B22,Malzemeler!$A$5:$A$100,0))),"Bilinmiyor")) | M22: =IF($B22="","",IFERROR(IF(INDEX(Malzemeler!$O$5:$O$100,MATCH($B22,Malzemeler!$A$5:$A$100,0))="","Bilinmiyor",INDEX(Malzemeler!$O$5:$O$100,MATCH($B22,Malzemeler!$A$5:$A$100,0))),"Bilinmiyor")) | N22: =IF($B22="","",IFERROR(IF(INDEX(Malzemeler!$P$5:$P$100,MATCH($B22,Malzemeler!$A$5:$A$100,0))="","Bilinmiyor",INDEX(Malzemeler!$P$5:$P$100,MATCH($B22,Malzemeler!$A$5:$A$100,0))),"Bilinmiyor")) | O22: =IF($B22="","",IFERROR(IF(INDEX(Malzemeler!$Q$5:$Q$100,MATCH($B22,Malzemeler!$A$5:$A$100,0))="","Bilinmiyor",INDEX(Malzemeler!$Q$5:$Q$100,MATCH($B22,Malzemeler!$A$5:$A$100,0))),"Bilinmiyor")) | P22: =IF($B22="","",IFERROR(IF(INDEX(Malzemeler!$R$5:$R$100,MATCH($B22,Malzemeler!$A$5:$A$100,0))="","Bilinmiyor",INDEX(Malzemeler!$R$5:$R$100,MATCH($B22,Malzemeler!$A$5:$A$100,0))),"Bilinmiyor"))
C23: =IF($B23="","",IFERROR(IF(INDEX(Malzemeler!$E$5:$E$100,MATCH($B23,Malzemeler!$A$5:$A$100,0))="","Bilinmiyor",INDEX(Malzemeler!$E$5:$E$100,MATCH($B23,Malzemeler!$A$5:$A$100,0))),"Bilinmiyor")) | D23: =IF($B23="","",IFERROR(IF(INDEX(Malzemeler!$F$5:$F$100,MATCH($B23,Malzemeler!$A$5:$A$100,0))="","Bilinmiyor",INDEX(Malzemeler!$F$5:$F$100,MATCH($B23,Malzemeler!$A$5:$A$100,0))),"Bilinmiyor")) | E23: =IF($B23="","",IFERROR(IF(INDEX(Malzemeler!$G$5:$G$100,MATCH($B23,Malzemeler!$A$5:$A$100,0))="","Bilinmiyor",INDEX(Malzemeler!$G$5:$G$100,MATCH($B23,Malzemeler!$A$5:$A$100,0))),"Bilinmiyor")) | F23: =IF($B23="","",IFERROR(IF(INDEX(Malzemeler!$H$5:$H$100,MATCH($B23,Malzemeler!$A$5:$A$100,0))="","Bilinmiyor",INDEX(Malzemeler!$H$5:$H$100,MATCH($B23,Malzemeler!$A$5:$A$100,0))),"Bilinmiyor")) | G23: =IF($B23="","",IFERROR(IF(INDEX(Malzemeler!$I$5:$I$100,MATCH($B23,Malzemeler!$A$5:$A$100,0))="","Bilinmiyor",INDEX(Malzemeler!$I$5:$I$100,MATCH($B23,Malzemeler!$A$5:$A$100,0))),"Bilinmiyor")) | H23: =IF($B23="","",IFERROR(IF(INDEX(Malzemeler!$J$5:$J$100,MATCH($B23,Malzemeler!$A$5:$A$100,0))="","Bilinmiyor",INDEX(Malzemeler!$J$5:$J$100,MATCH($B23,Malzemeler!$A$5:$A$100,0))),"Bilinmiyor")) | I23: =IF($B23="","",IFERROR(IF(INDEX(Malzemeler!$K$5:$K$100,MATCH($B23,Malzemeler!$A$5:$A$100,0))="","Bilinmiyor",INDEX(Malzemeler!$K$5:$K$100,MATCH($B23,Malzemeler!$A$5:$A$100,0))),"Bilinmiyor")) | J23: =IF($B23="","",IFERROR(IF(INDEX(Malzemeler!$L$5:$L$100,MATCH($B23,Malzemeler!$A$5:$A$100,0))="","Bilinmiyor",INDEX(Malzemeler!$L$5:$L$100,MATCH($B23,Malzemeler!$A$5:$A$100,0))),"Bilinmiyor")) | K23: =IF($B23="","",IFERROR(IF(INDEX(Malzemeler!$M$5:$M$100,MATCH($B23,Malzemeler!$A$5:$A$100,0))="","Bilinmiyor",INDEX(Malzemeler!$M$5:$M$100,MATCH($B23,Malzemeler!$A$5:$A$100,0))),"Bilinmiyor")) | L23: =IF($B23="","",IFERROR(IF(INDEX(Malzemeler!$N$5:$N$100,MATCH($B23,Malzemeler!$A$5:$A$100,0))="","Bilinmiyor",INDEX(Malzemeler!$N$5:$N$100,MATCH($B23,Malzemeler!$A$5:$A$100,0))),"Bilinmiyor")) | M23: =IF($B23="","",IFERROR(IF(INDEX(Malzemeler!$O$5:$O$100,MATCH($B23,Malzemeler!$A$5:$A$100,0))="","Bilinmiyor",INDEX(Malzemeler!$O$5:$O$100,MATCH($B23,Malzemeler!$A$5:$A$100,0))),"Bilinmiyor")) | N23: =IF($B23="","",IFERROR(IF(INDEX(Malzemeler!$P$5:$P$100,MATCH($B23,Malzemeler!$A$5:$A$100,0))="","Bilinmiyor",INDEX(Malzemeler!$P$5:$P$100,MATCH($B23,Malzemeler!$A$5:$A$100,0))),"Bilinmiyor")) | O23: =IF($B23="","",IFERROR(IF(INDEX(Malzemeler!$Q$5:$Q$100,MATCH($B23,Malzemeler!$A$5:$A$100,0))="","Bilinmiyor",INDEX(Malzemeler!$Q$5:$Q$100,MATCH($B23,Malzemeler!$A$5:$A$100,0))),"Bilinmiyor")) | P23: =IF($B23="","",IFERROR(IF(INDEX(Malzemeler!$R$5:$R$100,MATCH($B23,Malzemeler!$A$5:$A$100,0))="","Bilinmiyor",INDEX(Malzemeler!$R$5:$R$100,MATCH($B23,Malzemeler!$A$5:$A$100,0))),"Bilinmiyor"))
C24: =IF($B24="","",IFERROR(IF(INDEX(Malzemeler!$E$5:$E$100,MATCH($B24,Malzemeler!$A$5:$A$100,0))="","Bilinmiyor",INDEX(Malzemeler!$E$5:$E$100,MATCH($B24,Malzemeler!$A$5:$A$100,0))),"Bilinmiyor")) | D24: =IF($B24="","",IFERROR(IF(INDEX(Malzemeler!$F$5:$F$100,MATCH($B24,Malzemeler!$A$5:$A$100,0))="","Bilinmiyor",INDEX(Malzemeler!$F$5:$F$100,MATCH($B24,Malzemeler!$A$5:$A$100,0))),"Bilinmiyor")) | E24: =IF($B24="","",IFERROR(IF(INDEX(Malzemeler!$G$5:$G$100,MATCH($B24,Malzemeler!$A$5:$A$100,0))="","Bilinmiyor",INDEX(Malzemeler!$G$5:$G$100,MATCH($B24,Malzemeler!$A$5:$A$100,0))),"Bilinmiyor")) | F24: =IF($B24="","",IFERROR(IF(INDEX(Malzemeler!$H$5:$H$100,MATCH($B24,Malzemeler!$A$5:$A$100,0))="","Bilinmiyor",INDEX(Malzemeler!$H$5:$H$100,MATCH($B24,Malzemeler!$A$5:$A$100,0))),"Bilinmiyor")) | G24: =IF($B24="","",IFERROR(IF(INDEX(Malzemeler!$I$5:$I$100,MATCH($B24,Malzemeler!$A$5:$A$100,0))="","Bilinmiyor",INDEX(Malzemeler!$I$5:$I$100,MATCH($B24,Malzemeler!$A$5:$A$100,0))),"Bilinmiyor")) | H24: =IF($B24="","",IFERROR(IF(INDEX(Malzemeler!$J$5:$J$100,MATCH($B24,Malzemeler!$A$5:$A$100,0))="","Bilinmiyor",INDEX(Malzemeler!$J$5:$J$100,MATCH($B24,Malzemeler!$A$5:$A$100,0))),"Bilinmiyor")) | I24: =IF($B24="","",IFERROR(IF(INDEX(Malzemeler!$K$5:$K$100,MATCH($B24,Malzemeler!$A$5:$A$100,0))="","Bilinmiyor",INDEX(Malzemeler!$K$5:$K$100,MATCH($B24,Malzemeler!$A$5:$A$100,0))),"Bilinmiyor")) | J24: =IF($B24="","",IFERROR(IF(INDEX(Malzemeler!$L$5:$L$100,MATCH($B24,Malzemeler!$A$5:$A$100,0))="","Bilinmiyor",INDEX(Malzemeler!$L$5:$L$100,MATCH($B24,Malzemeler!$A$5:$A$100,0))),"Bilinmiyor")) | K24: =IF($B24="","",IFERROR(IF(INDEX(Malzemeler!$M$5:$M$100,MATCH($B24,Malzemeler!$A$5:$A$100,0))="","Bilinmiyor",INDEX(Malzemeler!$M$5:$M$100,MATCH($B24,Malzemeler!$A$5:$A$100,0))),"Bilinmiyor")) | L24: =IF($B24="","",IFERROR(IF(INDEX(Malzemeler!$N$5:$N$100,MATCH($B24,Malzemeler!$A$5:$A$100,0))="","Bilinmiyor",INDEX(Malzemeler!$N$5:$N$100,MATCH($B24,Malzemeler!$A$5:$A$100,0))),"Bilinmiyor")) | M24: =IF($B24="","",IFERROR(IF(INDEX(Malzemeler!$O$5:$O$100,MATCH($B24,Malzemeler!$A$5:$A$100,0))="","Bilinmiyor",INDEX(Malzemeler!$O$5:$O$100,MATCH($B24,Malzemeler!$A$5:$A$100,0))),"Bilinmiyor")) | N24: =IF($B24="","",IFERROR(IF(INDEX(Malzemeler!$P$5:$P$100,MATCH($B24,Malzemeler!$A$5:$A$100,0))="","Bilinmiyor",INDEX(Malzemeler!$P$5:$P$100,MATCH($B24,Malzemeler!$A$5:$A$100,0))),"Bilinmiyor")) | O24: =IF($B24="","",IFERROR(IF(INDEX(Malzemeler!$Q$5:$Q$100,MATCH($B24,Malzemeler!$A$5:$A$100,0))="","Bilinmiyor",INDEX(Malzemeler!$Q$5:$Q$100,MATCH($B24,Malzemeler!$A$5:$A$100,0))),"Bilinmiyor")) | P24: =IF($B24="","",IFERROR(IF(INDEX(Malzemeler!$R$5:$R$100,MATCH($B24,Malzemeler!$A$5:$A$100,0))="","Bilinmiyor",INDEX(Malzemeler!$R$5:$R$100,MATCH($B24,Malzemeler!$A$5:$A$100,0))),"Bilinmiyor"))
